Workbook

Sheet README
A1: Unit 11 - Individual Project: Executive Summary (Quantitative Risk Model)
A3: Purpose: estimate the probability and cost of quality, supply and continuity risks for the international, digitalised business.
A4: Method: Factor Analysis of Information Risk (FAIR) structure with Monte Carlo simulation; inputs are calibrated PERT (min, most likely, max) estimates.
A7: How to use:
A8: 1. Edit only the BLUE cells on the 'Inputs' sheet. Everything else recalculates.
A9: 2. 'Model' shows the deterministic results (expected values and closed-form probabilities).
A10: 3. 'Simulation' runs a live Monte Carlo (press F9 / recalc to reshuffle) and returns the mean and 90th/95th percentile loss.
A12: Colour code:
A13: Blue text = editable input (your assumption).
A14: Black text = formula / calculation.
A15: Green text = link to another sheet.
A16: Grey text = notes.
... A32: Results vary slightly each recalculation because the draws are random; more iterations give a smoother estimate.

Sheet Inputs
A1: Inputs (edit blue cells only)
A2: All blue cells are your assumptions. Sources go in the notes column.
A4: BUSINESS BASE (target scale)
A5: Assumption | B5: Low | C5: Most likely | D5: High | E5: Unit | L5: Source / notes
A6: Revenue | B6: 3000000 | C6: 7000000 | D6: 15000000 | E6: £ | L6: Modelled scale-up from ONS (2023), IBISWorld (2025), Pet Gazette (2025) anchors
A7: Gross margin | B7: 0.35 | C7: 0.45 | D7: 0.55 | E7: % | L7: Pet retail ~40% (trade sources); premium own-made higher
A8: Online share of revenue | B8: 0.25 | C8: 0.4 | D8: 0.6 | E8: % | L8: Sector e-commerce shift
A10: QUALITY RISKS (magnitude as % of revenue)
A11: Risk | B11: F low | C11: F ml | D11: F high | E11: V low | F11: V ml | G11: V high | H11: Mag% low | I11: Mag% ml | J11: Mag% high | L11: Evidence basis
A12: R1 Cold-chain excursion | B12: 1 | C12: 3 | D12: 8 | E12: 0.15 | F12: 0.3 | G12: 0.55 | H12: 0.001 | I12: 0.003 | J12: 0.01 | L12: R1, R2, R4: calibrated expert judgement - no firm-specific public data (weak/moderate knowledge)
A13: R2 Transit delay / spoilage | B13: 0.5 | C13: 2 | D13: 5 | E13: 0.1 | F13: 0.25 | G13: 0.5 | H13: 0.001 | I13: 0.004 | J13: 0.015 | L13: R3 recall frequency: anchored to FDA (~9 US pet-food recalls/yr industry-wide) and FSA recall data, scaled for a single premium producer with new international suppliers
A14: R3 Contamination / recall | B14: 0.1 | C14: 0.25 | D14: 0.8 | E14: 0.3 | F14: 0.6 | G14: 0.9 | H14: 0.02 | I14: 0.05 | J14: 0.1 | L14: R5 inter-hub variance: calibrated judgement; brand-critical, weak knowledge
A15: R4 Supplier quality drift | B15: 0.3 | C15: 1 | D15: 3 | E15: 0.2 | F15: 0.4 | G15: 0.7 | H15: 0.001 | I15: 0.0035 | J15: 0.012
A16: R5 Inter-hub variance | B16: 0.2 | C16: 0.6 | D16: 1.5 | E16: 0.4 | F16: 0.6 | G16: 0.85 | H16: 0.005 | I16: 0.01 | J16: 0.03
A18: F = events per year; V = P(quality harmed | event); Mag% = loss as a share of annual revenue.
A20: SUPPLY CHAIN
A21: Assumption | B21: Low | C21: Most likely | D21: High | L21: Notes
A22: Disruption frequency (/yr) | B22: 0.8 | C22: 1.5 | D22: 3.5 | L22: Supply frequency & duration: anchored to McKinsey (2020) - month-plus disruptions every 3.7 years (~0.27/yr)
A23: Disruption duration (days) | B23: 3 | C23: 10 | D23: 80
A24: Buffer stock (days) | B24: 42
A26: PRODUCTION HUBS
A27: Per-hub annual disruption probability (q) | B27: 0.05 | L27: Hub q: calibrated judgement (weak knowledge)
A29: ONLINE AVAILABILITY
A30: Target unplanned downtime (minutes/yr) | B30: 5.26 | L30: 5.26 = 99.999% ; 52.6 = 99.99%
A32: VENDOR LOCK-IN
A33: Assumption (£k) | B33: Low | C33: Most likely | D33: High | L33: Notes
A34: P(forced migration in horizon) | B34: 0.3
A35: Switch cost, high lock-in (£k) | B35: 350 | C35: 600 | D35: 1000 | L35: Switch costs reflect the ERP/WMS orchestrating the automated warehouses (operational, not just back-office); exit requires re-integrating physical fulfilment.
A36: Switch cost, low lock-in (£k) | B36: 100 | C36: 200 | D36: 400
A38: DATA BREACH
A39: Assumption | B39: Low | C39: Most likely | D39: High | L39: Notes
A40: P(reportable breach /yr) | B40: 0.15 | L40: Breach: anchored to IBM (2025) Cost of a Data Breach; UK average £3.29m used as upper bound; SME estimate below it
A41: Breach magnitude (% of revenue) | B41: 0.02 | C41: 0.04 | D41: 0.08

Sheet Model
A1: Deterministic Model (expected values and closed-form probabilities)
A2: All figures link to 'Inputs'. PERT mean = (low + 4×most likely + high) / 6.
A4: QUALITY
A5: Risk | B5: F mean | C5: V mean | D5: rate = F×V | E5: Mag mean (£) | F5: Expected loss (£) | H5: aF | I5: bF | J5: aV | K5: bV | L5: aMag | M5: bMag
A6: =Inputs!A12 -> R1 Cold-chain excursion | B6: =(Inputs!B12+4*Inputs!C12+Inputs!D12)/6 -> 3.5 | C6: =(Inputs!E12+4*Inputs!F12+Inputs!G12)/6 -> 0.31666667 | D6: =B6*C6 -> 1.1083333 | E6: =((Inputs!H12+4*Inputs!I12+Inputs!J12)/6)*Inputs!$C$6 -> 26833.333 | F6: =D6*E6 -> 29740.278 | H6: =1+4*(Inputs!C12-Inputs!B12)/(Inputs!D12-Inputs!B12) -> 2.1428571 | I6: =1+4*(Inputs!D12-Inputs!C12)/(Inputs!D12-Inputs!B12) -> 3.8571429 | J6: =1+4*(Inputs!F12-Inputs!E12)/(Inputs!G12-Inputs!E12) -> 2.5 | K6: =1+4*(Inputs!G12-Inputs!F12)/(Inputs!G12-Inputs!E12) -> 3.5 | L6: =1+4*(Inputs!I12-Inputs!H12)/(Inputs!J12-Inputs!H12) -> 1.8888889 | M6: =1+4*(Inputs!J12-Inputs!I12)/(Inputs!J12-Inputs!H12) -> 4.1111111
A7: =Inputs!A13 -> R2 Transit delay / spoilage | B7: =(Inputs!B13+4*Inputs!C13+Inputs!D13)/6 -> 2.25 | C7: =(Inputs!E13+4*Inputs!F13+Inputs!G13)/6 -> 0.26666667 | D7: =B7*C7 -> 0.6 | E7: =((Inputs!H13+4*Inputs!I13+Inputs!J13)/6)*Inputs!$C$6 -> 37333.333 | F7: =D7*E7 -> 22400 | H7: =1+4*(Inputs!C13-Inputs!B13)/(Inputs!D13-Inputs!B13) -> 2.3333333 | I7: =1+4*(Inputs!D13-Inputs!C13)/(Inputs!D13-Inputs!B13) -> 3.6666667 | J7: =1+4*(Inputs!F13-Inputs!E13)/(Inputs!G13-Inputs!E13) -> 2.5 | K7: =1+4*(Inputs!G13-Inputs!F13)/(Inputs!G13-Inputs!E13) -> 3.5 | L7: =1+4*(Inputs!I13-Inputs!H13)/(Inputs!J13-Inputs!H13) -> 1.8571429 | M7: =1+4*(Inputs!J13-Inputs!I13)/(Inputs!J13-Inputs!H13) -> 4.1428571
A8: =Inputs!A14 -> R3 Contamination / recall | B8: =(Inputs!B14+4*Inputs!C14+Inputs!D14)/6 -> 0.31666667 | C8: =(Inputs!E14+4*Inputs!F14+Inputs!G14)/6 -> 0.6 | D8: =B8*C8 -> 0.19 | E8: =((Inputs!H14+4*Inputs!I14+Inputs!J14)/6)*Inputs!$C$6 -> 373333.33 | F8: =D8*E8 -> 70933.333 | H8: =1+4*(Inputs!C14-Inputs!B14)/(Inputs!D14-Inputs!B14) -> 1.8571429 | I8: =1+4*(Inputs!D14-Inputs!C14)/(Inputs!D14-Inputs!B14) -> 4.1428571 | J8: =1+4*(Inputs!F14-Inputs!E14)/(Inputs!G14-Inputs!E14) -> 3 | K8: =1+4*(Inputs!G14-Inputs!F14)/(Inputs!G14-Inputs!E14) -> 3 | L8: =1+4*(Inputs!I14-Inputs!H14)/(Inputs!J14-Inputs!H14) -> 2.5 | M8: =1+4*(Inputs!J14-Inputs!I14)/(Inputs!J14-Inputs!H14) -> 3.5
A9: =Inputs!A15 -> R4 Supplier quality drift | B9: =(Inputs!B15+4*Inputs!C15+Inputs!D15)/6 -> 1.2166667 | C9: =(Inputs!E15+4*Inputs!F15+Inputs!G15)/6 -> 0.41666667 | D9: =B9*C9 -> 0.50694444 | E9: =((Inputs!H15+4*Inputs!I15+Inputs!J15)/6)*Inputs!$C$6 -> 31500 | F9: =D9*E9 -> 15968.75 | H9: =1+4*(Inputs!C15-Inputs!B15)/(Inputs!D15-Inputs!B15) -> 2.037037 | I9: =1+4*(Inputs!D15-Inputs!C15)/(Inputs!D15-Inputs!B15) -> 3.962963 | J9: =1+4*(Inputs!F15-Inputs!E15)/(Inputs!G15-Inputs!E15) -> 2.6 | K9: =1+4*(Inputs!G15-Inputs!F15)/(Inputs!G15-Inputs!E15) -> 3.4 | L9: =1+4*(Inputs!I15-Inputs!H15)/(Inputs!J15-Inputs!H15) -> 1.9090909 | M9: =1+4*(Inputs!J15-Inputs!I15)/(Inputs!J15-Inputs!H15) -> 4.0909091
A10: =Inputs!A16 -> R5 Inter-hub variance | B10: =(Inputs!B16+4*Inputs!C16+Inputs!D16)/6 -> 0.68333333 | C10: =(Inputs!E16+4*Inputs!F16+Inputs!G16)/6 -> 0.60833333 | D10: =B10*C10 -> 0.41569444 | E10: =((Inputs!H16+4*Inputs!I16+Inputs!J16)/6)*Inputs!$C$6 -> 87500 | F10: =D10*E10 -> 36373.264 | H10: =1+4*(Inputs!C16-Inputs!B16)/(Inputs!D16-Inputs!B16) -> 2.2307692 | I10: =1+4*(Inputs!D16-Inputs!C16)/(Inputs!D16-Inputs!B16) -> 3.7692308 | J10: =1+4*(Inputs!F16-Inputs!E16)/(Inputs!G16-Inputs!E16) -> 2.7777778 | K10: =1+4*(Inputs!G16-Inputs!F16)/(Inputs!G16-Inputs!E16) -> 3.2222222 | L10: =1+4*(Inputs!I16-Inputs!H16)/(Inputs!J16-Inputs!H16) -> 1.8 | M10: =1+4*(Inputs!J16-Inputs!I16)/(Inputs!J16-Inputs!H16) -> 4.2
A11: Total / result | D11: =SUM(D6:D10) -> 2.8209722 | F11: =SUM(F6:F10) -> 175415.62 | H11: Note
A13: P(≥1 quality-affecting event / yr) | B13: =1-EXP(-D11) -> 0.94045198
A14: P(serious / recall event, R3) / yr | B14: =1-EXP(-D8) -> 0.17304087
A15: P(brand-material inter-hub variance, R5) / yr | B15: =1-EXP(-D10) -> 0.34011813
A16: Expected annual quality loss (£) | B16: =F11 -> 175415.62
A19: DERIVED UNITS (at most-likely base)
A20: Revenue per day (£) | B20: =Inputs!C6/365 -> 19178.082
A21: Gross margin per day (£) | B21: =Inputs!C6*Inputs!C7/365 -> 8630.137
A22: Online revenue per minute (£) | B22: =Inputs!C6*Inputs!C8/525600 -> 5.3272451
A23: Online revenue per hour (£) | B23: =Inputs!C6*Inputs!C8/525600*60 -> 319.6347
A25: SUPPLY AVAILABILITY
A26: Disruption frequency mean (/yr) | B26: =(Inputs!B22+4*Inputs!C22+Inputs!D22)/6 -> 1.7166667
A27: Duration alpha / beta | B27: =1+4*(Inputs!C23-Inputs!B23)/(Inputs!D23-Inputs!B23) -> 1.3636364 | C27: =1+4*(Inputs!D23-Inputs!C23)/(Inputs!D23-Inputs!B23) -> 4.6363636
A28: Note: Buffer-exceeding (month-plus) disruption rate vs McKinsey (2020) ~0.27/yr (every 3.7 yrs)
A29: Buffer (days) | B29: P(≥1 stockout / yr)
A30: 14 | B30: =1-EXP(-B$26*(1-BETADIST((A30-Inputs!B23)/(Inputs!D23-Inputs!B23),B$27,C$27))) -> 0.66409876
A31: 21 | B31: =1-EXP(-B$26*(1-BETADIST((A31-Inputs!B23)/(Inputs!D23-Inputs!B23),B$27,C$27))) -> 0.50886971
A32: 28 | B32: =1-EXP(-B$26*(1-BETADIST((A32-Inputs!B23)/(Inputs!D23-Inputs!B23),B$27,C$27))) -> 0.34639894
A33: 42 | B33: =1-EXP(-B$26*(1-BETADIST((A33-Inputs!B23)/(Inputs!D23-Inputs!B23),B$27,C$27))) -> 0.10487549
A34: 60 | B34: =1-EXP(-B$26*(1-BETADIST((A34-Inputs!B23)/(Inputs!D23-Inputs!B23),B$27,C$27))) -> 0.006246476
A35: Stockout cost per day beyond buffer (£) = gross margin per day | B35: =Inputs!C6*Inputs!C7/365 -> 8630.137
A36: Note: buffer alone cannot cover month-plus disruptions; dual sourcing and multi-hub redundancy are the primary controls.
A38: PRODUCTION-HUB AVAILABILITY
A39: P(≥2 of 3 hubs down) = 3q²(1−q)+q³ | B39: =3*Inputs!B27^2*(1-Inputs!B27)+Inputs!B27^3 -> 0.00725
A41: ONLINE DOWNTIME (direct lost sales)
A42: Direct lost online sales at target downtime (£/yr) | B42: =Inputs!C6*Inputs!C8/525600*Inputs!B30 -> 28.021309
A43: Note: direct cost is small; the requirement is justified by reputation, not transactions.
A45: VENDOR LOCK-IN
A46: Switch cost high-lock mean (£k) | B46: =(Inputs!B35+4*Inputs!C35+Inputs!D35)/6 -> 625
A47: Switch cost low-lock mean (£k) | B47: =(Inputs!B36+4*Inputs!C36+Inputs!D36)/6 -> 216.66667
A48: Decision value of low-lock platform (£k) | B48: =Inputs!B34*(B46-B47) -> 122.5
...

Sheet Simulation
A2: Summary (simulated annual quality loss)
A3: Mean (£) | C3: =AVERAGE(AK12:AK1011) -> 169364.74
A4: Median P50 (£) | C4: =MEDIAN(AK12:AK1011) -> 108457.25
A5: P90 (£) | C5: =PERCENTILE(AK12:AK1011,0.9) -> 448901.86
A6: P95 (£) | C6: =PERCENTILE(AK12:AK1011,0.95) -> 560636.32
A8: Live Monte Carlo (Quality Loss). Recalculate (F9) to reshuffle.
A9: 1000 iterations. Each row samples F, V and magnitude from their PERT distributions and draws a Poisson event count.
B11: R1 F | C11: R1 V | D11: R1 mag | E11: R1 r | F11: R1 u | G11: R1 count | H11: R1 loss | I11: R2 F | J11: R2 V | K11: R2 mag | L11: R2 r | M11: R2 u | N11: R2 count | O11: R2 loss | P11: R3 F | Q11: R3 V | R11: R3 mag | S11: R3 r | T11: R3 u | U11: R3 count | V11: R3 loss | W11: R4 F | X11: R4 V | Y11: R4 mag | Z11: R4 r | AA11: R4 u | AB11: R4 count | AC11: R4 loss | AD11: R5 F | AE11: R5 V | AF11: R5 mag | AG11: R5 r | AH11: R5 u | AI11: R5 count | AJ11: R5 loss | AK11: Total loss
B12: =Inputs!B12+(Inputs!D12-Inputs!B12)*BETAINV(RAND(),Model!H6,Model!I6) -> 3.4165347 | C12: =Inputs!E12+(Inputs!G12-Inputs!E12)*BETAINV(RAND(),Model!J6,Model!K6) -> 0.31316026 | D12: =(Inputs!H12+(Inputs!J12-Inputs!H12)*BETAINV(RAND(),Model!L6,Model!M6))*Inputs!$C$6 -> 41359.902 | E12: =B12*C12 -> 1.0699229 | F12: =RAND() -> 0.4657148 | G12: =IF(F12<EXP(-E12),0,IF(F12<EXP(-E12)*(1+E12),1,IF(F12<EXP(-E12)*(1+E12+E12^2/2),2,IF(F12<EXP(-E12)*(1+E12+E12^2/2+E12^3/6),3,4)))) -> 1 | H12: =G12*D12 -> 41359.902 | I12: =Inputs!B13+(Inputs!D13-Inputs!B13)*BETAINV(RAND(),Model!H7,Model!I7) -> 1.1863252 | J12: =Inputs!E13+(Inputs!G13-Inputs!E13)*BETAINV(RAND(),Model!J7,Model!K7) -> 0.22191204 | K12: =(Inputs!H13+(Inputs!J13-Inputs!H13)*BETAINV(RAND(),Model!L7,Model!M7))*Inputs!$C$6 -> 36519.383 | L12: =I12*J12 -> 0.26325985 | M12: =RAND() -> 0.034776356 | N12: =IF(M12<EXP(-L12),0,IF(M12<EXP(-L12)*(1+L12),1,IF(M12<EXP(-L12)*(1+L12+L12^2/2),2,IF(M12<EXP(-L12)*(1+L12+L12^2/2+L12^3/6),3,4)))) -> 0 | O12: =N12*K12 -> 0 | P12: =Inputs!B14+(Inputs!D14-Inputs!B14)*BETAINV(RAND(),Model!H8,Model!I8) -> 0.32088482 | Q12: =Inputs!E14+(Inputs!G14-Inputs!E14)*BETAINV(RAND(),Model!J8,Model!K8) -> 0.74627 | R12: =(Inputs!H14+(Inputs!J14-Inputs!H14)*BETAINV(RAND(),Model!L8,Model!M8))*Inputs!$C$6 -> 305314.33 | S12: =P12*Q12 -> 0.23946672 | T12: =RAND() -> 0.57242786 | U12: =IF(T12<EXP(-S12),0,IF(T12<EXP(-S12)*(1+S12),1,IF(T12<EXP(-S12)*(1+S12+S12^2/2),2,IF(T12<EXP(-S12)*(1+S12+S12^2/2+S12^3/6),3,4)))) -> 0 | V12: =U12*R12 -> 0 | W12: =Inputs!B15+(Inputs!D15-Inputs!B15)*BETAINV(RAND(),Model!H9,Model!I9) -> 0.94597771 | X12: =Inputs!E15+(Inputs!G15-Inputs!E15)*BETAINV(RAND(),Model!J9,Model!K9) -> 0.45775815 | Y12: =(Inputs!H15+(Inputs!J15-Inputs!H15)*BETAINV(RAND(),Model!L9,Model!M9))*Inputs!$C$6 -> 36525.799 | Z12: =W12*X12 -> 0.43302901 | AA12: =RAND() -> 0.86745177 | AB12: =IF(AA12<EXP(-Z12),0,IF(AA12<EXP(-Z12)*(1+Z12),1,IF(AA12<EXP(-Z12)*(1+Z12+Z12^2/2),2,IF(AA12<EXP(-Z12)*(1+Z12+Z12^2/2+Z12^3/6),3,4)))) -> 1 | AC12: =AB12*Y12 -> 36525.799 | AD12: =Inputs!B16+(Inputs!D16-Inputs!B16)*BETAINV(RAND(),Model!H10,Model!I10) -> 0.64015975 | AE12: =Inputs!E16+(Inputs!G16-Inputs!E16)*BETAINV(RAND(),Model!J10,Model!K10) -> 0.71937545 | AF12: =(Inputs!H16+(Inputs!J16-Inputs!H16)*BETAINV(RAND(),Model!L10,Model!M10))*Inputs!$C$6 -> 54267.671 | AG12: =AD12*AE12 -> 0.4605152 | AH12: =RAND() -> 0.58134215 | AI12: =IF(AH12<EXP(-AG12),0,IF(AH12<EXP(-AG12)*(1+AG12),1,IF(AH12<EXP(-AG12)*(1+AG12+AG12^2/2),2,IF(AH12<EXP(-AG12)*(1+AG12+AG12^2/2+AG12^3/6),3,4)))) -> 0 | AJ12: =AI12*AF12 -> 0 | AK12: =H12+O12+V12+AC12+AJ12 -> 77885.701
B13: =Inputs!B12+(Inputs!D12-Inputs!B12)*BETAINV(RAND(),Model!H6,Model!I6) -> 5.4429746 | C13: =Inputs!E12+(Inputs!G12-Inputs!E12)*BETAINV(RAND(),Model!J6,Model!K6) -> 0.29735871 | D13: =(Inputs!H12+(Inputs!J12-Inputs!H12)*BETAINV(RAND(),Model!L6,Model!M6))*Inputs!$C$6 -> 16457.73 | E13: =B13*C13 -> 1.6185159 | F13: =RAND() -> 0.25949383 | G13: =IF(F13<EXP(-E13),0,IF(F13<EXP(-E13)*(1+E13),1,IF(F13<EXP(-E13)*(1+E13+E13^2/2),2,IF(F13<EXP(-E13)*(1+E13+E13^2/2+E13^3/6),3,4)))) -> 1 | H13: =G13*D13 -> 16457.73 | I13: =Inputs!B13+(Inputs!D13-Inputs!B13)*BETAINV(RAND(),Model!H7,Model!I7) -> 4.0373127 | J13: =Inputs!E13+(Inputs!G13-Inputs!E13)*BETAINV(RAND(),Model!J7,Model!K7) -> 0.11849302 | K13: =(Inputs!H13+(Inputs!J13-Inputs!H13)*BETAINV(RAND(),Model!L7,Model!M7))*Inputs!$C$6 -> 53135.487 | L13: =I13*J13 -> 0.47839337 | M13: =RAND() -> 0.68089845 | N13: =IF(M13<EXP(-L13),0,IF(M13<EXP(-L13)*(1+L13),1,IF(M13<EXP(-L13)*(1+L13+L13^2/2),2,IF(M13<EXP(-L13)*(1+L13+L13^2/2+L13^3/6),3,4)))) -> 1 | O13: =N13*K13 -> 53135.487 | P13: =Inputs!B14+(Inputs!D14-Inputs!B14)*BETAINV(RAND(),Model!H8,Model!I8) -> 0.14119605 | Q13: =Inputs!E14+(Inputs!G14-Inputs!E14)*BETAINV(RAND(),Model!J8,Model!K8) -> 0.50185527 | R13: =(Inputs!H14+(Inputs!J14-Inputs!H14)*BETAINV(RAND(),Model!L8,Model!M8))*Inputs!$C$6 -> 402787.1 | S13: =P13*Q13 -> 0.07085998 | T13: =RAND() -> 0.61598315 | U13: =IF(T13<EXP(-S13),0,IF(T13<EXP(-S13)*(1+S13),1,IF(T13<EXP(-S13)*(1+S13+S13^2/2),2,IF(T13<EXP(-S13)*(1+S13+S13^2/2+S13^3/6),3,4)))) -> 0 | V13: =U13*R13 -> 0 | W13: =Inputs!B15+(Inputs!D15-Inputs!B15)*BETAINV(RAND(),Model!H9,Model!I9) -> 1.7765996 | X13: =Inputs!E15+(Inputs!G15-Inputs!E15)*BETAINV(RAND(),Model!J9,Model!K9) -> 0.39590983 | Y13: =(Inputs!H15+(Inputs!J15-Inputs!H15)*BETAINV(RAND(),Model!L9,Model!M9))*Inputs!$C$6 -> 15957.161 | Z13: =W13*X13 -> 0.70337325 | AA13: =RAND() -> 0.1285682 | AB13: =IF(AA13<EXP(-Z13),0,IF(AA13<EXP(-Z13)*(1+Z13),1,IF(AA13<EXP(-Z13)*(1+Z13+Z13^2/2),2,IF(AA13<EXP(-Z13)*(1+Z13+Z13^2/2+Z13^3/6),3,4)))) -> 0 | AC13: =AB13*Y13 -> 0 | AD13: =Inputs!B16+(Inputs!D16-Inputs!B16)*BETAINV(RAND(),Model!H10,Model!I10) -> 0.93868527 | AE13: =Inputs!E16+(Inputs!G16-Inputs!E16)*BETAINV(RAND(),Model!J10,Model!K10) -> 0.72143336 | AF13: =(Inputs!H16+(Inputs!J16-Inputs!H16)*BETAINV(RAND(),Model!L10,Model!M10))*Inputs!$C$6 -> 50063.419 | AG13: =AD13*AE13 -> 0.67719886 | AH13: =RAND() -> 0.61853357 | AI13: =IF(AH13<EXP(-AG13),0,IF(AH13<EXP(-AG13)*(1+AG13),1,IF(AH13<EXP(-AG13)*(1+AG13+AG13^2/2),2,IF(AH13<EXP(-AG13)*(1+AG13+AG13^2/2+AG13^3/6),3,4)))) -> 1 | AJ13: =AI13*AF13 -> 50063.419 | AK13: =H13+O13+V13+AC13+AJ13 -> 119656.64
B14: =Inputs!B12+(Inputs!D12-Inputs!B12)*BETAINV(RAND(),Model!H6,Model!I6) -> 2.8991463 | C14: =Inputs!E12+(Inputs!G12-Inputs!E12)*BETAINV(RAND(),Model!J6,Model!K6) -> 0.41195147 | D14: =(Inputs!H12+(Inputs!J12-Inputs!H12)*BETAINV(RAND(),Model!L6,Model!M6))*Inputs!$C$6 -> 42590.997 | E14: =B14*C14 -> 1.1943076 | F14: =RAND() -> 0.33104784 | G14: =IF(F14<EXP(-E14),0,IF(F14<EXP(-E14)*(1+E14),1,IF(F14<EXP(-E14)*(1+E14+E14^2/2),2,IF(F14<EXP(-E14)*(1+E14+E14^2/2+E14^3/6),3,4)))) -> 1 | H14: =G14*D14 -> 42590.997 | I14: =Inputs!B13+(Inputs!D13-Inputs!B13)*BETAINV(RAND(),Model!H7,Model!I7) -> 1.0032515 | J14: =Inputs!E13+(Inputs!G13-Inputs!E13)*BETAINV(RAND(),Model!J7,Model!K7) -> 0.29159952 | K14: =(Inputs!H13+(Inputs!J13-Inputs!H13)*BETAINV(RAND(),Model!L7,Model!M7))*Inputs!$C$6 -> 19381.31 | L14: =I14*J14 -> 0.29254765 | M14: =RAND() -> 0.24340115 | N14: =IF(M14<EXP(-L14),0,IF(M14<EXP(-L14)*(1+L14),1,IF(M14<EXP(-L14)*(1+L14+L14^2/2),2,IF(M14<EXP(-L14)*(1+L14+L14^2/2+L14^3/6),3,4)))) -> 0 | O14: =N14*K14 -> 0 | P14: =Inputs!B14+(Inputs!D14-Inputs!B14)*BETAINV(RAND(),Model!H8,Model!I8) -> 0.32022509 | Q14: =Inputs!E14+(Inputs!G14-Inputs!E14)*BETAINV(RAND(),Model!J8,Model!K8) -> 0.70678778 | R14: =(Inputs!H14+(Inputs!J14-Inputs!H14)*BETAINV(RAND(),Model!L8,Model!M8))*Inputs!$C$6 -> 449728.62 | S14: =P14*Q14 -> 0.22633118 | T14: =RAND() -> 0.37312027 | U14: =IF(T14<EXP(-S14),0,IF(T14<EXP(-S14)*(1+S14),1,IF(T14<EXP(-S14)*(1+S14+S14^2/2),2,IF(T14<EXP(-S14)*(1+S14+S14^2/2+S14^3/6),3,4)))) -> 0 | V14: =U14*R14 -> 0 | W14: =Inputs!B15+(Inputs!D15-Inputs!B15)*BETAINV(RAND(),Model!H9,Model!I9) -> 0.81317782 | X14: =Inputs!E15+(Inputs!G15-Inputs!E15)*BETAINV(RAND(),Model!J9,Model!K9) -> 0.46827302 | Y14: =(Inputs!H15+(Inputs!J15-Inputs!H15)*BETAINV(RAND(),Model!L9,Model!M9))*Inputs!$C$6 -> 20800.509 | Z14: =W14*X14 -> 0.38078923 | AA14: =RAND() -> 0.4811397 | AB14: =IF(AA14<EXP(-Z14),0,IF(AA14<EXP(-Z14)*(1+Z14),1,IF(AA14<EXP(-Z14)*(1+Z14+Z14^2/2),2,IF(AA14<EXP(-Z14)*(1+Z14+Z14^2/2+Z14^3/6),3,4)))) -> 0 | AC14: =AB14*Y14 -> 0 | AD14: =Inputs!B16+(Inputs!D16-Inputs!B16)*BETAINV(RAND(),Model!H10,Model!I10) -> 0.59719583 | AE14: =Inputs!E16+(Inputs!G16-Inputs!E16)*BETAINV(RAND(),Model!J10,Model!K10) -> 0.62925625 | AF14: =(Inputs!H16+(Inputs!J16-Inputs!H16)*BETAINV(RAND(),Model!L10,Model!M10))*Inputs!$C$6 -> 59409.463 | AG14: =AD14*AE14 -> 0.37578921 | AH14: =RAND() -> 0.64361128 | AI14: =IF(AH14<EXP(-AG14),0,IF(AH14<EXP(-AG14)*(1+AG14),1,IF(AH14<EXP(-AG14)*(1+AG14+AG14^2/2),2,IF(AH14<EXP(-AG14)*(1+AG14+AG14^2/2+AG14^3/6),3,4)))) -> 0 | AJ14: =AI14*AF14 -> 0 | AK14: =H14+O14+V14+AC14+AJ14 -> 42590.997
B15: =Inputs!B12+(Inputs!D12-Inputs!B12)*BETAINV(RAND(),Model!H6,Model!I6) -> 3.1062039 | C15: =Inputs!E12+(Inputs!G12-Inputs!E12)*BETAINV(RAND(),Model!J6,Model!K6) -> 0.2325814 | D15: =(Inputs!H12+(Inputs!J12-Inputs!H12)*BETAINV(RAND(),Model!L6,Model!M6))*Inputs!$C$6 -> 41334.516 | E15: =B15*C15 -> 0.72244526 | F15: =RAND() -> 0.17740048 | G15: =IF(F15<EXP(-E15),0,IF(F15<EXP(-E15)*(1+E15),1,IF(F15<EXP(-E15)*(1+E15+E15^2/2),2,IF(F15<EXP(-E15)*(1+E15+E15^2/2+E15^3/6),3,4)))) -> 0 | H15: =G15*D15 -> 0 | I15: =Inputs!B13+(Inputs!D13-Inputs!B13)*BETAINV(RAND(),Model!H7,Model!I7) -> 1.3763275 | J15: =Inputs!E13+(Inputs!G13-Inputs!E13)*BETAINV(RAND(),Model!J7,Model!K7) -> 0.2621962 | K15: =(Inputs!H13+(Inputs!J13-Inputs!H13)*BETAINV(RAND(),Model!L7,Model!M7))*Inputs!$C$6 -> 32745.011 | L15: =I15*J15 -> 0.36086783 | M15: =RAND() -> 0.77824605 | N15: =IF(M15<EXP(-L15),0,IF(M15<EXP(-L15)*(1+L15),1,IF(M15<EXP(-L15)*(1+L15+L15^2/2),2,IF(M15<EXP(-L15)*(1+L15+L15^2/2+L15^3/6),3,4)))) -> 1 | O15: =N15*K15 -> 32745.011 | P15: =Inputs!B14+(Inputs!D14-Inputs!B14)*BETAINV(RAND(),Model!H8,Model!I8) -> 0.29640393 | Q15: =Inputs!E14+(Inputs!G14-Inputs!E14)*BETAINV(RAND(),Model!J8,Model!K8) -> 0.63665011 | R15: =(Inputs!H14+(Inputs!J14-Inputs!H14)*BETAINV(RAND(),Model!L8,Model!M8))*Inputs!$C$6 -> 347386.17 | S15: =P15*Q15 -> 0.1887056 | T15: =RAND() -> 0.76026681 | U15: =IF(T15<EXP(-S15),0,IF(T15<EXP(-S15)*(1+S15),1,IF(T15<EXP(-S15)*(1+S15+S15^2/2),2,IF(T15<EXP(-S15)*(1+S15+S15^2/2+S15^3/6),3,4)))) -> 0 | V15: =U15*R15 -> 0 | W15: =Inputs!B15+(Inputs!D15-Inputs!B15)*BETAINV(RAND(),Model!H9,Model!I9) -> 1.176182 | X15: =Inputs!E15+(Inputs!G15-Inputs!E15)*BETAINV(RAND(),Model!J9,Model!K9) -> 0.41457 | Y15: =(Inputs!H15+(Inputs!J15-Inputs!H15)*BETAINV(RAND(),Model!L9,Model!M9))*Inputs!$C$6 -> 8903.9126 | Z15: =W15*X15 -> 0.48760976 | AA15: =RAND() -> 0.90978053 | AB15: =IF(AA15<EXP(-Z15),0,IF(AA15<EXP(-Z15)*(1+Z15),1,IF(AA15<EXP(-Z15)*(1+Z15+Z15^2/2),2,IF(AA15<EXP(-Z15)*(1+Z15+Z15^2/2+Z15^3/6),3,4)))) -> 1 | AC15: =AB15*Y15 -> 8903.9126 | AD15: =Inputs!B16+(Inputs!D16-Inputs!B16)*BETAINV(RAND(),Model!H10,Model!I10) -> 0.80086208 | AE15: =Inputs!E16+(Inputs!G16-Inputs!E16)*BETAINV(RAND(),Model!J10,Model!K10) -> 0.61256528 | AF15: =(Inputs!H16+(Inputs!J16-Inputs!H16)*BETAINV(RAND(),Model!L10,Model!M10))*Inputs!$C$6 -> 135329.18 | AG15: =AD15*AE15 -> 0.4905803 | AH15: =RAND() -> 0.78986386 | AI15: =IF(AH15<EXP(-AG15),0,IF(AH15<EXP(-AG15)*(1+AG15),1,IF(AH15<EXP(-AG15)*(1+AG15+AG15^2/2),2,IF(AH15<EXP(-AG15)*(1+AG15+AG15^2/2+AG15^3/6),3,4)))) -> 1 | AJ15: =AI15*AF15 -> 135329.18 | AK15: =H15+O15+V15+AC15+AJ15 -> 176978.1
B16: =Inputs!B12+(Inputs!D12-Inputs!B12)*BETAINV(RAND(),Model!H6,Model!I6) -> 5.9129646 | C16: =Inputs!E12+(Inputs!G12-Inputs!E12)*BETAINV(RAND(),Model!J6,Model!K6) -> 0.4025378 | D16: =(Inputs!H12+(Inputs!J12-Inputs!H12)*BETAINV(RAND(),Model!L6,Model!M6))*Inputs!$C$6 -> 39701.745 | E16: =B16*C16 -> 2.3801918 | F16: =RAND() -> 0.70868742 | G16: =IF(F16<EXP(-E16),0,IF(F16<EXP(-E16)*(1+E16),1,IF(F16<EXP(-E16)*(1+E16+E16^2/2),2,IF(F16<EXP(-E16)*(1+E16+E16^2/2+E16^3/6),3,4)))) -> 3 | H16: =G16*D16 -> 119105.23 | I16: =Inputs!B13+(Inputs!D13-Inputs!B13)*BETAINV(RAND(),Model!H7,Model!I7) -> 2.7671966 | J16: =Inputs!E13+(Inputs!G13-Inputs!E13)*BETAINV(RAND(),Model!J7,Model!K7) -> 0.30764682 | K16: =(Inputs!H13+(Inputs!J13-Inputs!H13)*BETAINV(RAND(),Model!L7,Model!M7))*Inputs!$C$6 -> 21385 | L16: =I16*J16 -> 0.85131923 | M16: =RAND() -> 0.60139844 | N16: =IF(M16<EXP(-L16),0,IF(M16<EXP(-L16)*(1+L16),1,IF(M16<EXP(-L16)*(1+L16+L16^2/2),2,IF(M16<EXP(-L16)*(1+L16+L16^2/2+L16^3/6),3,4)))) -> 1 | O16: =N16*K16 -> 21385 | P16: =Inputs!B14+(Inputs!D14-Inputs!B14)*BETAINV(RAND(),Model!H8,Model!I8) -> 0.20545386 | Q16: =Inputs!E14+(Inputs!G14-Inputs!E14)*BETAINV(RAND(),Model!J8,Model!K8) -> 0.68454722 | R16: =(Inputs!H14+(Inputs!J14-Inputs!H14)*BETAINV(RAND(),Model!L8,Model!M8))*Inputs!$C$6 -> 218634.55 | S16: =P16*Q16 -> 0.14064287 | T16: =RAND() -> 0.9570384 | U16: =IF(T16<EXP(-S16),0,IF(T16<EXP(-S16)*(1+S16),1,IF(T16<EXP(-S16)*(1+S16+S16^2/2),2,IF(T16<EXP(-S16)*(1+S16+S16^2/2+S16^3/6),3,4)))) -> 1 | V16: =U16*R16 -> 218634.55 | W16: =Inputs!B15+(Inputs!D15-Inputs!B15)*BETAINV(RAND(),Model!H9,Model!I9) -> 0.60560441 | X16: =Inputs!E15+(Inputs!G15-Inputs!E15)*BETAINV(RAND(),Model!J9,Model!K9) -> 0.55196421 | Y16: =(Inputs!H15+(Inputs!J15-Inputs!H15)*BETAINV(RAND(),Model!L9,Model!M9))*Inputs!$C$6 -> 44288.16 | Z16: =W16*X16 -> 0.33427196 | AA16: =RAND() -> 0.53184467 | AB16: =IF(AA16<EXP(-Z16),0,IF(AA16<EXP(-Z16)*(1+Z16),1,IF(AA16<EXP(-Z16)*(1+Z16+Z16^2/2),2,IF(AA16<EXP(-Z16)*(1+Z16+Z16^2/2+Z16^3/6),3,4)))) -> 0 | AC16: =AB16*Y16 -> 0 | AD16: =Inputs!B16+(Inputs!D16-Inputs!B16)*BETAINV(RAND(),Model!H10,Model!I10) -> 0.45475867 | AE16: =Inputs!E16+(Inputs!G16-Inputs!E16)*BETAINV(RAND(),Model!J10,Model!K10) -> 0.67974321 | AF16: =(Inputs!H16+(Inputs!J16-Inputs!H16)*BETAINV(RAND(),Model!L10,Model!M10))*Inputs!$C$6 -> 49901.083 | AG16: =AD16*AE16 -> 0.30911912 | AH16: =RAND() -> 0.89003832 | AI16: =IF(AH16<EXP(-AG16),0,IF(AH16<EXP(-AG16)*(1+AG16),1,IF(AH16<EXP(-AG16)*(1+AG16+AG16^2/2),2,IF(AH16<EXP(-AG16)*(1+AG16+AG16^2/2+AG16^3/6),3,4)))) -> 1 | AJ16: =AI16*AF16 -> 49901.083 | AK16: =H16+O16+V16+AC16+AJ16 -> 409025.87
B17: =Inputs!B12+(Inputs!D12-Inputs!B12)*BETAINV(RAND(),Model!H6,Model!I6) -> 3.1553492 | C17: =Inputs!E12+(Inputs!G12-Inputs!E12)*BETAINV(RAND(),Model!J6,Model!K6) -> 0.39684416 | D17: =(Inputs!H12+(Inputs!J12-Inputs!H12)*BETAINV(RAND(),Model!L6,Model!M6))*Inputs!$C$6 -> 17691.137 | E17: =B17*C17 -> 1.2521819 | F17: =RAND() -> 0.10368429 | G17: =IF(F17<EXP(-E17),0,IF(F17<EXP(-E17)*(1+E17),1,IF(F17<EXP(-E17)*(1+E17+E17^2/2),2,IF(F17<EXP(-E17)*(1+E17+E17^2/2+E17^3/6),3,4)))) -> 0 | H17: =G17*D17 -> 0 | I17: =Inputs!B13+(Inputs!D13-Inputs!B13)*BETAINV(RAND(),Model!H7,Model!I7) -> 3.389889 | J17: =Inputs!E13+(Inputs!G13-Inputs!E13)*BETAINV(RAND(),Model!J7,Model!K7) -> 0.23746264 | K17: =(Inputs!H13+(Inputs!J13-Inputs!H13)*BETAINV(RAND(),Model!L7,Model!M7))*Inputs!$C$6 -> 23019.067 | L17: =I17*J17 -> 0.80497199 | M17: =RAND() -> 0.69091639 | N17: =IF(M17<EXP(-L17),0,IF(M17<EXP(-L17)*(1+L17),1,IF(M17<EXP(-L17)*(1+L17+L17^2/2),2,IF(M17<EXP(-L17)*(1+L17+L17^2/2+L17^3/6),3,4)))) -> 1 | O17: =N17*K17 -> 23019.067 | P17: =Inputs!B14+(Inputs!D14-Inputs!B14)*BETAINV(RAND(),Model!H8,Model!I8) -> 0.10720353 | Q17: =Inputs!E14+(Inputs!G14-Inputs!E14)*BETAINV(RAND(),Model!J8,Model!K8) -> 0.38870894 | R17: =(Inputs!H14+(Inputs!J14-Inputs!H14)*BETAINV(RAND(),Model!L8,Model!M8))*Inputs!$C$6 -> 400601.45 | S17: =P17*Q17 -> 0.041670972 | T17: =RAND() -> 0.86820865 | U17: =IF(T17<EXP(-S17),0,IF(T17<EXP(-S17)*(1+S17),1,IF(T17<EXP(-S17)*(1+S17+S17^2/2),2,IF(T17<EXP(-S17)*(1+S17+S17^2/2+S17^3/6),3,4)))) -> 0 | V17: =U17*R17 -> 0 | W17: =Inputs!B15+(Inputs!D15-Inputs!B15)*BETAINV(RAND(),Model!H9,Model!I9) -> 0.67078613 | X17: =Inputs!E15+(Inputs!G15-Inputs!E15)*BETAINV(RAND(),Model!J9,Model!K9) -> 0.34618287 | Y17: =(Inputs!H15+(Inputs!J15-Inputs!H15)*BETAINV(RAND(),Model!L9,Model!M9))*Inputs!$C$6 -> 43094.271 | Z17: =W17*X17 -> 0.23221467 | AA17: =RAND() -> 0.71802798 | AB17: =IF(AA17<EXP(-Z17),0,IF(AA17<EXP(-Z17)*(1+Z17),1,IF(AA17<EXP(-Z17)*(1+Z17+Z17^2/2),2,IF(AA17<EXP(-Z17)*(1+Z17+Z17^2/2+Z17^3/6),3,4)))) -> 0 | AC17: =AB17*Y17 -> 0 | AD17: =Inputs!B16+(Inputs!D16-Inputs!B16)*BETAINV(RAND(),Model!H10,Model!I10) -> 0.36642392 | AE17: =Inputs!E16+(Inputs!G16-Inputs!E16)*BETAINV(RAND(),Model!J10,Model!K10) -> 0.65114406 | AF17: =(Inputs!H16+(Inputs!J16-Inputs!H16)*BETAINV(RAND(),Model!L10,Model!M10))*Inputs!$C$6 -> 89205.405 | AG17: =AD17*AE17 -> 0.23859476 | AH17: =RAND() -> 0.15812745 | AI17: =IF(AH17<EXP(-AG17),0,IF(AH17<EXP(-AG17)*(1+AG17),1,IF(AH17<EXP(-AG17)*(1+AG17+AG17^2/2),2,IF(AH17<EXP(-AG17)*(1+AG17+AG17^2/2+AG17^3/6),3,4)))) -> 0 | AJ17: =AI17*AF17 -> 0 | AK17: =H17+O17+V17+AC17+AJ17 -> 23019.067
B18: =Inputs!B12+(Inputs!D12-Inputs!B12)*BETAINV(RAND(),Model!H6,Model!I6) -> 3.4842229 | C18: =Inputs!E12+(Inputs!G12-Inputs!E12)*BETAINV(RAND(),Model!J6,Model!K6) -> 0.39478271 | D18: =(Inputs!H12+(Inputs!J12-Inputs!H12)*BETAINV(RAND(),Model!L6,Model!M6))*Inputs!$C$6 -> 25136.965 | E18: =B18*C18 -> 1.375511 | F18: =RAND() -> 0.2660267 | G18: =IF(F18<EXP(-E18),0,IF(F18<EXP(-E18)*(1+E18),1,IF(F18<EXP(-E18)*(1+E18+E18^2/2),2,IF(F18<EXP(-E18)*(1+E18+E18^2/2+E18^3/6),3,4)))) -> 1 | H18: =G18*D18 -> 25136.965 | I18: =Inputs!B13+(Inputs!D13-Inputs!B13)*BETAINV(RAND(),Model!H7,Model!I7) -> 3.3925084 | J18: =Inputs!E13+(Inputs!G13-Inputs!E13)*BETAINV(RAND(),Model!J7,Model!K7) -> 0.28075184 | K18: =(Inputs!H13+(Inputs!J13-Inputs!H13)*BETAINV(RAND(),Model!L7,Model!M7))*Inputs!$C$6 -> 34995.011 | L18: =I18*J18 -> 0.95245297 | M18: =RAND() -> 0.5027459 | N18: =IF(M18<EXP(-L18),0,IF(M18<EXP(-L18)*(1+L18),1,IF(M18<EXP(-L18)*(1+L18+L18^2/2),2,IF(M18<EXP(-L18)*(1+L18+L18^2/2+L18^3/6),3,4)))) -> 1 | O18: =N18*K18 -> 34995.011 | P18: =Inputs!B14+(Inputs!D14-Inputs!B14)*BETAINV(RAND(),Model!H8,Model!I8) -> 0.5468183 | Q18: =Inputs!E14+(Inputs!G14-Inputs!E14)*BETAINV(RAND(),Model!J8,Model!K8) -> 0.64008899 | R18: =(Inputs!H14+(Inputs!J14-Inputs!H14)*BETAINV(RAND(),Model!L8,Model!M8))*Inputs!$C$6 -> 417999.12 | S18: =P18*Q18 -> 0.35001238 | T18: =RAND() -> 0.30975258 | U18: =IF(T18<EXP(-S18),0,IF(T18<EXP(-S18)*(1+S18),1,IF(T18<EXP(-S18)*(1+S18+S18^2/2),2,IF(T18<EXP(-S18)*(1+S18+S18^2/2+S18^3/6),3,4)))) -> 0 | V18: =U18*R18 -> 0 | W18: =Inputs!B15+(Inputs!D15-Inputs!B15)*BETAINV(RAND(),Model!H9,Model!I9) -> 1.0984893 | X18: =Inputs!E15+(Inputs!G15-Inputs!E15)*BETAINV(RAND(),Model!J9,Model!K9) -> 0.42697035 | Y18: =(Inputs!H15+(Inputs!J15-Inputs!H15)*BETAINV(RAND(),Model!L9,Model!M9))*Inputs!$C$6 -> 24932.013 | Z18: =W18*X18 -> 0.46902236 | AA18: =RAND() -> 0.49412264 | AB18: =IF(AA18<EXP(-Z18),0,IF(AA18<EXP(-Z18)*(1+Z18),1,IF(AA18<EXP(-Z18)*(1+Z18+Z18^2/2),2,IF(AA18<EXP(-Z18)*(1+Z18+Z18^2/2+Z18^3/6),3,4)))) -> 0 | AC18: =AB18*Y18 -> 0 | AD18: =Inputs!B16+(Inputs!D16-Inputs!B16)*BETAINV(RAND(),Model!H10,Model!I10) -> 0.47049608 | AE18: =Inputs!E16+(Inputs!G16-Inputs!E16)*BETAINV(RAND(),Model!J10,Model!K10) -> 0.59865082 | AF18: =(Inputs!H16+(Inputs!J16-Inputs!H16)*BETAINV(RAND(),Model!L10,Model!M10))*Inputs!$C$6 -> 153198.2 | AG18: =AD18*AE18 -> 0.28166287 | AH18: =RAND() -> 0.30628843 | AI18: =IF(AH18<EXP(-AG18),0,IF(AH18<EXP(-AG18)*(1+AG18),1,IF(AH18<EXP(-AG18)*(1+AG18+AG18^2/2),2,IF(AH18<EXP(-AG18)*(1+AG18+AG18^2/2+AG18^3/6),3,4)))) -> 0 | AJ18: =AI18*AF18 -> 0 | AK18: =H18+O18+V18+AC18+AJ18 -> 60131.977
B19: =Inputs!B12+(Inputs!D12-Inputs!B12)*BETAINV(RAND(),Model!H6,Model!I6) -> 2.8640426 | C19: =Inputs!E12+(Inputs!G12-Inputs!E12)*BETAINV(RAND(),Model!J6,Model!K6) -> 0.24602936 | D19: =(Inputs!H12+(Inputs!J12-Inputs!H12)*BETAINV(RAND(),Model!L6,Model!M6))*Inputs!$C$6 -> 27677.501 | E19: =B19*C19 -> 0.70463858 | F19: =RAND() -> 0.54010905 | G19: =IF(F19<EXP(-E19),0,IF(F19<EXP(-E19)*(1+E19),1,IF(F19<EXP(-E19)*(1+E19+E19^2/2),2,IF(F19<EXP(-E19)*(1+E19+E19^2/2+E19^3/6),3,4)))) -> 1 | H19: =G19*D19 -> 27677.501 | I19: =Inputs!B13+(Inputs!D13-Inputs!B13)*BETAINV(RAND(),Model!H7,Model!I7) -> 2.9176737 | J19: =Inputs!E13+(Inputs!G13-Inputs!E13)*BETAINV(RAND(),Model!J7,Model!K7) -> 0.27069899 | K19: =(Inputs!H13+(Inputs!J13-Inputs!H13)*BETAINV(RAND(),Model!L7,Model!M7))*Inputs!$C$6 -> 45870.341 | L19: =I19*J19 -> 0.78981131 | M19: =RAND() -> 0.59045157 | N19: =IF(M19<EXP(-L19),0,IF(M19<EXP(-L19)*(1+L19),1,IF(M19<EXP(-L19)*(1+L19+L19^2/2),2,IF(M19<EXP(-L19)*(1+L19+L19^2/2+L19^3/6),3,4)))) -> 1 | O19: =N19*K19 -> 45870.341 | P19: =Inputs!B14+(Inputs!D14-Inputs!B14)*BETAINV(RAND(),Model!H8,Model!I8) -> 0.42335802 | Q19: =Inputs!E14+(Inputs!G14-Inputs!E14)*BETAINV(RAND(),Model!J8,Model!K8) -> 0.76955233 | R19: =(Inputs!H14+(Inputs!J14-Inputs!H14)*BETAINV(RAND(),Model!L8,Model!M8))*Inputs!$C$6 -> 358899.1 | S19: =P19*Q19 -> 0.32579615 | T19: =RAND() -> 0.18440905 | U19: =IF(T19<EXP(-S19),0,IF(T19<EXP(-S19)*(1+S19),1,IF(T19<EXP(-S19)*(1+S19+S19^2/2),2,IF(T19<EXP(-S19)*(1+S19+S19^2/2+S19^3/6),3,4)))) -> 0 | V19: =U19*R19 -> 0 | W19: =Inputs!B15+(Inputs!D15-Inputs!B15)*BETAINV(RAND(),Model!H9,Model!I9) -> 1.2530663 | X19: =Inputs!E15+(Inputs!G15-Inputs!E15)*BETAINV(RAND(),Model!J9,Model!K9) -> 0.40297761 | Y19: =(Inputs!H15+(Inputs!J15-Inputs!H15)*BETAINV(RAND(),Model!L9,Model!M9))*Inputs!$C$6 -> 24613.818 | Z19: =W19*X19 -> 0.50495767 | AA19: =RAND() -> 0.38160911 | AB19: =IF(AA19<EXP(-Z19),0,IF(AA19<EXP(-Z19)*(1+Z19),1,IF(AA19<EXP(-Z19)*(1+Z19+Z19^2/2),2,IF(AA19<EXP(-Z19)*(1+Z19+Z19^2/2+Z19^3/6),3,4)))) -> 0 | AC19: =AB19*Y19 -> 0 | AD19: =Inputs!B16+(Inputs!D16-Inputs!B16)*BETAINV(RAND(),Model!H10,Model!I10) -> 0.54438929 | AE19: =Inputs!E16+(Inputs!G16-Inputs!E16)*BETAINV(RAND(),Model!J10,Model!K10) -> 0.64681665 | AF19: =(Inputs!H16+(Inputs!J16-Inputs!H16)*BETAINV(RAND(),Model!L10,Model!M10))*Inputs!$C$6 -> 110267.93 | AG19: =AD19*AE19 -> 0.35212006 | AH19: =RAND() -> 0.67628015 | AI19: =IF(AH19<EXP(-AG19),0,IF(AH19<EXP(-AG19)*(1+AG19),1,IF(AH19<EXP(-AG19)*(1+AG19+AG19^2/2),2,IF(AH19<EXP(-AG19)*(1+AG19+AG19^2/2+AG19^3/6),3,4)))) -> 0 | AJ19: =AI19*AF19 -> 0 | AK19: =H19+O19+V19+AC19+AJ19 -> 73547.841
B20: =Inputs!B12+(Inputs!D12-Inputs!B12)*BETAINV(RAND(),Model!H6,Model!I6) -> 2.3587697 | C20: =Inputs!E12+(Inputs!G12-Inputs!E12)*BETAINV(RAND(),Model!J6,Model!K6) -> 0.23373169 | D20: =(Inputs!H12+(Inputs!J12-Inputs!H12)*BETAINV(RAND(),Model!L6,Model!M6))*Inputs!$C$6 -> 13966.411 | E20: =B20*C20 -> 0.55131925 | F20: =RAND() -> 0.97033965 | G20: =IF(F20<EXP(-E20),0,IF(F20<EXP(-E20)*(1+E20),1,IF(F20<EXP(-E20)*(1+E20+E20^2/2),2,IF(F20<EXP(-E20)*(1+E20+E20^2/2+E20^3/6),3,4)))) -> 2 | H20: =G20*D20 -> 27932.822 | I20: =Inputs!B13+(Inputs!D13-Inputs!B13)*BETAINV(RAND(),Model!H7,Model!I7) -> 2.8069922 | J20: =Inputs!E13+(Inputs!G13-Inputs!E13)*BETAINV(RAND(),Model!J7,Model!K7) -> 0.29649235 | K20: =(Inputs!H13+(Inputs!J13-Inputs!H13)*BETAINV(RAND(),Model!L7,Model!M7))*Inputs!$C$6 -> 28012.502 | L20: =I20*J20 -> 0.83225171 | M20: =RAND() -> 0.25864642 | N20: =IF(M20<EXP(-L20),0,IF(M20<EXP(-L20)*(1+L20),1,IF(M20<EXP(-L20)*(1+L20+L20^2/2),2,IF(M20<EXP(-L20)*(1+L20+L20^2/2+L20^3/6),3,4)))) -> 0 | O20: =N20*K20 -> 0 | P20: =Inputs!B14+(Inputs!D14-Inputs!B14)*BETAINV(RAND(),Model!H8,Model!I8) -> 0.34864255 | Q20: =Inputs!E14+(Inputs!G14-Inputs!E14)*BETAINV(RAND(),Model!J8,Model!K8) -> 0.56609475 | R20: =(Inputs!H14+(Inputs!J14-Inputs!H14)*BETAINV(RAND(),Model!L8,Model!M8))*Inputs!$C$6 -> 378010.42 | S20: =P20*Q20 -> 0.19736472 | T20: =RAND() -> 0.78487766 | U20: =IF(T20<EXP(-S20),0,IF(T20<EXP(-S20)*(1+S20),1,IF(T20<EXP(-S20)*(1+S20+S20^2/2),2,IF(T20<EXP(-S20)*(1+S20+S20^2/2+S20^3/6),3,4)))) -> 0 | V20: =U20*R20 -> 0 | W20: =Inputs!B15+(Inputs!D15-Inputs!B15)*BETAINV(RAND(),Model!H9,Model!I9) -> 1.3744486 | X20: =Inputs!E15+(Inputs!G15-Inputs!E15)*BETAINV(RAND(),Model!J9,Model!K9) -> 0.29964296 | Y20: =(Inputs!H15+(Inputs!J15-Inputs!H15)*BETAINV(RAND(),Model!L9,Model!M9))*Inputs!$C$6 -> 7934.702 | Z20: =W20*X20 -> 0.41184384 | AA20: =RAND() -> 0.372176 | AB20: =IF(AA20<EXP(-Z20),0,IF(AA20<EXP(-Z20)*(1+Z20),1,IF(AA20<EXP(-Z20)*(1+Z20+Z20^2/2),2,IF(AA20<EXP(-Z20)*(1+Z20+Z20^2/2+Z20^3/6),3,4)))) -> 0 | AC20: =AB20*Y20 -> 0 | AD20: =Inputs!B16+(Inputs!D16-Inputs!B16)*BETAINV(RAND(),Model!H10,Model!I10) -> 0.56272526 | AE20: =Inputs!E16+(Inputs!G16-Inputs!E16)*BETAINV(RAND(),Model!J10,Model!K10) -> 0.63322424 | AF20: =(Inputs!H16+(Inputs!J16-Inputs!H16)*BETAINV(RAND(),Model!L10,Model!M10))*Inputs!$C$6 -> 96935.119 | AG20: =AD20*AE20 -> 0.35633128 | AH20: =RAND() -> 0.38561731 | AI20: =IF(AH20<EXP(-AG20),0,IF(AH20<EXP(-AG20)*(1+AG20),1,IF(AH20<EXP(-AG20)*(1+AG20+AG20^2/2),2,IF(AH20<EXP(-AG20)*(1+AG20+AG20^2/2+AG20^3/6),3,4)))) -> 0 | AJ20: =AI20*AF20 -> 0 | AK20: =H20+O20+V20+AC20+AJ20 -> 27932.822
B21: =Inputs!B12+(Inputs!D12-Inputs!B12)*BETAINV(RAND(),Model!H6,Model!I6) -> 5.0512907 | C21: =Inputs!E12+(Inputs!G12-Inputs!E12)*BETAINV(RAND(),Model!J6,Model!K6) -> 0.39977197 | D21: =(Inputs!H12+(Inputs!J12-Inputs!H12)*BETAINV(RAND(),Model!L6,Model!M6))*Inputs!$C$6 -> 39215.857 | E21: =B21*C21 -> 2.0193645 | F21: =RAND() -> 0.7368181 | G21: =IF(F21<EXP(-E21),0,IF(F21<EXP(-E21)*(1+E21),1,IF(F21<EXP(-E21)*(1+E21+E21^2/2),2,IF(F21<EXP(-E21)*(1+E21+E21^2/2+E21^3/6),3,4)))) -> 3 | H21: =G21*D21 -> 117647.57 | I21: =Inputs!B13+(Inputs!D13-Inputs!B13)*BETAINV(RAND(),Model!H7,Model!I7) -> 1.1119548 | J21: =Inputs!E13+(Inputs!G13-Inputs!E13)*BETAINV(RAND(),Model!J7,Model!K7) -> 0.34349203 | K21: =(Inputs!H13+(Inputs!J13-Inputs!H13)*BETAINV(RAND(),Model!L7,Model!M7))*Inputs!$C$6 -> 45992.634 | L21: =I21*J21 -> 0.38194761 | M21: =RAND() -> 0.22827819 | N21: =IF(M21<EXP(-L21),0,IF(M21<EXP(-L21)*(1+L21),1,IF(M21<EXP(-L21)*(1+L21+L21^2/2),2,IF(M21<EXP(-L21)*(1+L21+L21^2/2+L21^3/6),3,4)))) -> 0 | O21: =N21*K21 -> 0 | P21: =Inputs!B14+(Inputs!D14-Inputs!B14)*BETAINV(RAND(),Model!H8,Model!I8) -> 0.14868196 | Q21: =Inputs!E14+(Inputs!G14-Inputs!E14)*BETAINV(RAND(),Model!J8,Model!K8) -> 0.60007131 | R21: =(Inputs!H14+(Inputs!J14-Inputs!H14)*BETAINV(RAND(),Model!L8,Model!M8))*Inputs!$C$6 -> 383614.81 | S21: =P21*Q21 -> 0.089219777 | T21: =RAND() -> 0.37974076 | U21: =IF(T21<EXP(-S21),0,IF(T21<EXP(-S21)*(1+S21),1,IF(T21<EXP(-S21)*(1+S21+S21^2/2),2,IF(T21<EXP(-S21)*(1+S21+S21^2/2+S21^3/6),3,4)))) -> 0 | V21: =U21*R21 -> 0 | W21: =Inputs!B15+(Inputs!D15-Inputs!B15)*BETAINV(RAND(),Model!H9,Model!I9) -> 0.86581828 | X21: =Inputs!E15+(Inputs!G15-Inputs!E15)*BETAINV(RAND(),Model!J9,Model!K9) -> 0.27436001 | Y21: =(Inputs!H15+(Inputs!J15-Inputs!H15)*BETAINV(RAND(),Model!L9,Model!M9))*Inputs!$C$6 -> 57697.424 | Z21: =W21*X21 -> 0.23754591 | AA21: =RAND() -> 0.70175482 | AB21: =IF(AA21<EXP(-Z21),0,IF(AA21<EXP(-Z21)*(1+Z21),1,IF(AA21<EXP(-Z21)*(1+Z21+Z21^2/2),2,IF(AA21<EXP(-Z21)*(1+Z21+Z21^2/2+Z21^3/6),3,4)))) -> 0 | AC21: =AB21*Y21 -> 0 | AD21: =Inputs!B16+(Inputs!D16-Inputs!B16)*BETAINV(RAND(),Model!H10,Model!I10) -> 0.67751859 | AE21: =Inputs!E16+(Inputs!G16-Inputs!E16)*BETAINV(RAND(),Model!J10,Model!K10) -> 0.50915121 | AF21: =(Inputs!H16+(Inputs!J16-Inputs!H16)*BETAINV(RAND(),Model!L10,Model!M10))*Inputs!$C$6 -> 121211.7 | AG21: =AD21*AE21 -> 0.34495941 | AH21: =RAND() -> 0.021768727 | AI21: =IF(AH21<EXP(-AG21),0,IF(AH21<EXP(-AG21)*(1+AG21),1,IF(AH21<EXP(-AG21)*(1+AG21+AG21^2/2),2,IF(AH21<EXP(-AG21)*(1+AG21+AG21^2/2+AG21^3/6),3,4)))) -> 0 | AJ21: =AI21*AF21 -> 0 | AK21: =H21+O21+V21+AC21+AJ21 -> 117647.57
B22: =Inputs!B12+(Inputs!D12-Inputs!B12)*BETAINV(RAND(),Model!H6,Model!I6) -> 1.8416677 | C22: =Inputs!E12+(Inputs!G12-Inputs!E12)*BETAINV(RAND(),Model!J6,Model!K6) -> 0.22221065 | D22: =(Inputs!H12+(Inputs!J12-Inputs!H12)*BETAINV(RAND(),Model!L6,Model!M6))*Inputs!$C$6 -> 43370.524 | E22: =B22*C22 -> 0.40923819 | F22: =RAND() -> 0.8671523 | G22: =IF(F22<EXP(-E22),0,IF(F22<EXP(-E22)*(1+E22),1,IF(F22<EXP(-E22)*(1+E22+E22^2/2),2,IF(F22<EXP(-E22)*(1+E22+E22^2/2+E22^3/6),3,4)))) -> 1 | H22: =G22*D22 -> 43370.524 | I22: =Inputs!B13+(Inputs!D13-Inputs!B13)*BETAINV(RAND(),Model!H7,Model!I7) -> 2.3492192 | J22: =Inputs!E13+(Inputs!G13-Inputs!E13)*BETAINV(RAND(),Model!J7,Model!K7) -> 0.21677072 | K22: =(Inputs!H13+(Inputs!J13-Inputs!H13)*BETAINV(RAND(),Model!L7,Model!M7))*Inputs!$C$6 -> 18922.497 | L22: =I22*J22 -> 0.50924195 | M22: =RAND() -> 0.57014561 | N22: =IF(M22<EXP(-L22),0,IF(M22<EXP(-L22)*(1+L22),1,IF(M22<EXP(-L22)*(1+L22+L22^2/2),2,IF(M22<EXP(-L22)*(1+L22+L22^2/2+L22^3/6),3,4)))) -> 0 | O22: =N22*K22 -> 0 | P22: =Inputs!B14+(Inputs!D14-Inputs!B14)*BETAINV(RAND(),Model!H8,Model!I8) -> 0.27912457 | Q22: =Inputs!E14+(Inputs!G14-Inputs!E14)*BETAINV(RAND(),Model!J8,Model!K8) -> 0.67655033 | R22: =(Inputs!H14+(Inputs!J14-Inputs!H14)*BETAINV(RAND(),Model!L8,Model!M8))*Inputs!$C$6 -> 270913.07 | S22: =P22*Q22 -> 0.18884182 | T22: =RAND() -> 0.83932724 | U22: =IF(T22<EXP(-S22),0,IF(T22<EXP(-S22)*(1+S22),1,IF(T22<EXP(-S22)*(1+S22+S22^2/2),2,IF(T22<EXP(-S22)*(1+S22+S22^2/2+S22^3/6),3,4)))) -> 1 | V22: =U22*R22 -> 270913.07 | W22: =Inputs!B15+(Inputs!D15-Inputs!B15)*BETAINV(RAND(),Model!H9,Model!I9) -> 1.5062166 | X22: =Inputs!E15+(Inputs!G15-Inputs!E15)*BETAINV(RAND(),Model!J9,Model!K9) -> 0.64690933 | Y22: =(Inputs!H15+(Inputs!J15-Inputs!H15)*BETAINV(RAND(),Model!L9,Model!M9))*Inputs!$C$6 -> 55665.747 | Z22: =W22*X22 -> 0.97438559 | AA22: =RAND() -> 0.01798646 | AB22: =IF(AA22<EXP(-Z22),0,IF(AA22<EXP(-Z22)*(1+Z22),1,IF(AA22<EXP(-Z22)*(1+Z22+Z22^2/2),2,IF(AA22<EXP(-Z22)*(1+Z22+Z22^2/2+Z22^3/6),3,4)))) -> 0 | AC22: =AB22*Y22 -> 0 | AD22: =Inputs!B16+(Inputs!D16-Inputs!B16)*BETAINV(RAND(),Model!H10,Model!I10) -> 1.067885 | AE22: =Inputs!E16+(Inputs!G16-Inputs!E16)*BETAINV(RAND(),Model!J10,Model!K10) -> 0.49888607 | AF22: =(Inputs!H16+(Inputs!J16-Inputs!H16)*BETAINV(RAND(),Model!L10,Model!M10))*Inputs!$C$6 -> 63665.707 | AG22: =AD22*AE22 -> 0.53275295 | AH22: =RAND() -> 0.092621616 | AI22: =IF(AH22<EXP(-AG22),0,IF(AH22<EXP(-AG22)*(1+AG22),1,IF(AH22<EXP(-AG22)*(1+AG22+AG22^2/2),2,IF(AH22<EXP(-AG22)*(1+AG22+AG22^2/2+AG22^3/6),3,4)))) -> 0 | AJ22: =AI22*AF22 -> 0 | AK22: =H22+O22+V22+AC22+AJ22 -> 314283.6
B23: =Inputs!B12+(Inputs!D12-Inputs!B12)*BETAINV(RAND(),Model!H6,Model!I6) -> 5.0364066 | C23: =Inputs!E12+(Inputs!G12-Inputs!E12)*BETAINV(RAND(),Model!J6,Model!K6) -> 0.17366164 | D23: =(Inputs!H12+(Inputs!J12-Inputs!H12)*BETAINV(RAND(),Model!L6,Model!M6))*Inputs!$C$6 -> 30669.595 | E23: =B23*C23 -> 0.87463061 | F23: =RAND() -> 0.4754431 | G23: =IF(F23<EXP(-E23),0,IF(F23<EXP(-E23)*(1+E23),1,IF(F23<EXP(-E23)*(1+E23+E23^2/2),2,IF(F23<EXP(-E23)*(1+E23+E23^2/2+E23^3/6),3,4)))) -> 1 | H23: =G23*D23 -> 30669.595 | I23: =Inputs!B13+(Inputs!D13-Inputs!B13)*BETAINV(RAND(),Model!H7,Model!I7) -> 2.7203644 | J23: =Inputs!E13+(Inputs!G13-Inputs!E13)*BETAINV(RAND(),Model!J7,Model!K7) -> 0.35380611 | K23: =(Inputs!H13+(Inputs!J13-Inputs!H13)*BETAINV(RAND(),Model!L7,Model!M7))*Inputs!$C$6 -> 31497.623 | L23: =I23*J23 -> 0.96248154 | M23: =RAND() -> 0.31180461 | N23: =IF(M23<EXP(-L23),0,IF(M23<EXP(-L23)*(1+L23),1,IF(M23<EXP(-L23)*(1+L23+L23^2/2),2,IF(M23<EXP(-L23)*(1+L23+L23^2/2+L23^3/6),3,4)))) -> 0 | O23: =N23*K23 -> 0 | P23: =Inputs!B14+(Inputs!D14-Inputs!B14)*BETAINV(RAND(),Model!H8,Model!I8) -> 0.22793242 | Q23: =Inputs!E14+(Inputs!G14-Inputs!E14)*BETAINV(RAND(),Model!J8,Model!K8) -> 0.71668091 | R23: =(Inputs!H14+(Inputs!J14-Inputs!H14)*BETAINV(RAND(),Model!L8,Model!M8))*Inputs!$C$6 -> 209096.04 | S23: =P23*Q23 -> 0.16335481 | T23: =RAND() -> 0.88648937 | U23: =IF(T23<EXP(-S23),0,IF(T23<EXP(-S23)*(1+S23),1,IF(T23<EXP(-S23)*(1+S23+S23^2/2),2,IF(T23<EXP(-S23)*(1+S23+S23^2/2+S23^3/6),3,4)))) -> 1 | V23: =U23*R23 -> 209096.04 | W23: =Inputs!B15+(Inputs!D15-Inputs!B15)*BETAINV(RAND(),Model!H9,Model!I9) -> 0.64192755 | X23: =Inputs!E15+(Inputs!G15-Inputs!E15)*BETAINV(RAND(),Model!J9,Model!K9) -> 0.49449238 | Y23: =(Inputs!H15+(Inputs!J15-Inputs!H15)*BETAINV(RAND(),Model!L9,Model!M9))*Inputs!$C$6 -> 36338.158 | Z23: =W23*X23 -> 0.31742828 | AA23: =RAND() -> 0.85094406 | AB23: =IF(AA23<EXP(-Z23),0,IF(AA23<EXP(-Z23)*(1+Z23),1,IF(AA23<EXP(-Z23)*(1+Z23+Z23^2/2),2,IF(AA23<EXP(-Z23)*(1+Z23+Z23^2/2+Z23^3/6),3,4)))) -> 1 | AC23: =AB23*Y23 -> 36338.158 | AD23: =Inputs!B16+(Inputs!D16-Inputs!B16)*BETAINV(RAND(),Model!H10,Model!I10) -> 0.98903091 | AE23: =Inputs!E16+(Inputs!G16-Inputs!E16)*BETAINV(RAND(),Model!J10,Model!K10) -> 0.72302428 | AF23: =(Inputs!H16+(Inputs!J16-Inputs!H16)*BETAINV(RAND(),Model!L10,Model!M10))*Inputs!$C$6 -> 52329.569 | AG23: =AD23*AE23 -> 0.71509336 | AH23: =RAND() -> 0.17638155 | AI23: =IF(AH23<EXP(-AG23),0,IF(AH23<EXP(-AG23)*(1+AG23),1,IF(AH23<EXP(-AG23)*(1+AG23+AG23^2/2),2,IF(AH23<EXP(-AG23)*(1+AG23+AG23^2/2+AG23^3/6),3,4)))) -> 0 | AJ23: =AI23*AF23 -> 0 | AK23: =H23+O23+V23+AC23+AJ23 -> 276103.79
B24: =Inputs!B12+(Inputs!D12-Inputs!B12)*BETAINV(RAND(),Model!H6,Model!I6) -> 2.7130798 | C24: =Inputs!E12+(Inputs!G12-Inputs!E12)*BETAINV(RAND(),Model!J6,Model!K6) -> 0.2723294 | D24: =(Inputs!H12+(Inputs!J12-Inputs!H12)*BETAINV(RAND(),Model!L6,Model!M6))*Inputs!$C$6 -> 27387.14 | E24: =B24*C24 -> 0.7388514 | F24: =RAND() -> 0.099620321 | G24: =IF(F24<EXP(-E24),0,IF(F24<EXP(-E24)*(1+E24),1,IF(F24<EXP(-E24)*(1+E24+E24^2/2),2,IF(F24<EXP(-E24)*(1+E24+E24^2/2+E24^3/6),3,4)))) -> 0 | H24: =G24*D24 -> 0 | I24: =Inputs!B13+(Inputs!D13-Inputs!B13)*BETAINV(RAND(),Model!H7,Model!I7) -> 1.3980574 | J24: =Inputs!E13+(Inputs!G13-Inputs!E13)*BETAINV(RAND(),Model!J7,Model!K7) -> 0.2729067 | K24: =(Inputs!H13+(Inputs!J13-Inputs!H13)*BETAINV(RAND(),Model!L7,Model!M7))*Inputs!$C$6 -> 34275.218 | L24: =I24*J24 -> 0.38153924 | M24: =RAND() -> 0.54601699 | N24: =IF(M24<EXP(-L24),0,IF(M24<EXP(-L24)*(1+L24),1,IF(M24<EXP(-L24)*(1+L24+L24^2/2),2,IF(M24<EXP(-L24)*(1+L24+L24^2/2+L24^3/6),3,4)))) -> 0 | O24: =N24*K24 -> 0 | P24: =Inputs!B14+(Inputs!D14-Inputs!B14)*BETAINV(RAND(),Model!H8,Model!I8) -> 0.18288642 | Q24: =Inputs!E14+(Inputs!G14-Inputs!E14)*BETAINV(RAND(),Model!J8,Model!K8) -> 0.50082552 | R24: =(Inputs!H14+(Inputs!J14-Inputs!H14)*BETAINV(RAND(),Model!L8,Model!M8))*Inputs!$C$6 -> 323601.88 | S24: =P24*Q24 -> 0.091594186 | T24: =RAND() -> 0.26822627 | U24: =IF(T24<EXP(-S24),0,IF(T24<EXP(-S24)*(1+S24),1,IF(T24<EXP(-S24)*(1+S24+S24^2/2),2,IF(T24<EXP(-S24)*(1+S24+S24^2/2+S24^3/6),3,4)))) -> 0 | V24: =U24*R24 -> 0 | W24: =Inputs!B15+(Inputs!D15-Inputs!B15)*BETAINV(RAND(),Model!H9,Model!I9) -> 2.0088556 | X24: =Inputs!E15+(Inputs!G15-Inputs!E15)*BETAINV(RAND(),Model!J9,Model!K9) -> 0.43905206 | Y24: =(Inputs!H15+(Inputs!J15-Inputs!H15)*BETAINV(RAND(),Model!L9,Model!M9))*Inputs!$C$6 -> 26305.859 | Z24: =W24*X24 -> 0.88199218 | AA24: =RAND() -> 0.9122106 | AB24: =IF(AA24<EXP(-Z24),0,IF(AA24<EXP(-Z24)*(1+Z24),1,IF(AA24<EXP(-Z24)*(1+Z24+Z24^2/2),2,IF(AA24<EXP(-Z24)*(1+Z24+Z24^2/2+Z24^3/6),3,4)))) -> 2 | AC24: =AB24*Y24 -> 52611.717 | AD24: =Inputs!B16+(Inputs!D16-Inputs!B16)*BETAINV(RAND(),Model!H10,Model!I10) -> 0.66787453 | AE24: =Inputs!E16+(Inputs!G16-Inputs!E16)*BETAINV(RAND(),Model!J10,Model!K10) -> 0.69216401 | AF24: =(Inputs!H16+(Inputs!J16-Inputs!H16)*BETAINV(RAND(),Model!L10,Model!M10))*Inputs!$C$6 -> 129947.53 | AG24: =AD24*AE24 -> 0.46227872 | AH24: =RAND() -> 0.10147126 | AI24: =IF(AH24<EXP(-AG24),0,IF(AH24<EXP(-AG24)*(1+AG24),1,IF(AH24<EXP(-AG24)*(1+AG24+AG24^2/2),2,IF(AH24<EXP(-AG24)*(1+AG24+AG24^2/2+AG24^3/6),3,4)))) -> 0 | AJ24: =AI24*AF24 -> 0 | AK24: =H24+O24+V24+AC24+AJ24 -> 52611.717
B25: =Inputs!B12+(Inputs!D12-Inputs!B12)*BETAINV(RAND(),Model!H6,Model!I6) -> 3.0670855 | C25: =Inputs!E12+(Inputs!G12-Inputs!E12)*BETAINV(RAND(),Model!J6,Model!K6) -> 0.3415103 | D25: =(Inputs!H12+(Inputs!J12-Inputs!H12)*BETAINV(RAND(),Model!L6,Model!M6))*Inputs!$C$6 -> 44996.741 | E25: =B25*C25 -> 1.0474413 | F25: =RAND() -> 0.031746829 | G25: =IF(F25<EXP(-E25),0,IF(F25<EXP(-E25)*(1+E25),1,IF(F25<EXP(-E25)*(1+E25+E25^2/2),2,IF(F25<EXP(-E25)*(1+E25+E25^2/2+E25^3/6),3,4)))) -> 0 | H25: =G25*D25 -> 0 | I25: =Inputs!B13+(Inputs!D13-Inputs!B13)*BETAINV(RAND(),Model!H7,Model!I7) -> 2.2188865 | J25: =Inputs!E13+(Inputs!G13-Inputs!E13)*BETAINV(RAND(),Model!J7,Model!K7) -> 0.3698465 | K25: =(Inputs!H13+(Inputs!J13-Inputs!H13)*BETAINV(RAND(),Model!L7,Model!M7))*Inputs!$C$6 -> 39233.974 | L25: =I25*J25 -> 0.82064741 | M25: =RAND() -> 0.60879566 | N25: =IF(M25<EXP(-L25),0,IF(M25<EXP(-L25)*(1+L25),1,IF(M25<EXP(-L25)*(1+L25+L25^2/2),2,IF(M25<EXP(-L25)*(1+L25+L25^2/2+L25^3/6),3,4)))) -> 1 | O25: =N25*K25 -> 39233.974 | P25: =Inputs!B14+(Inputs!D14-Inputs!B14)*BETAINV(RAND(),Model!H8,Model!I8) -> 0.39653423 | Q25: =Inputs!E14+(Inputs!G14-Inputs!E14)*BETAINV(RAND(),Model!J8,Model!K8) -> 0.62784833 | R25: =(Inputs!H14+(Inputs!J14-Inputs!H14)*BETAINV(RAND(),Model!L8,Model!M8))*Inputs!$C$6 -> 195402.68 | S25: =P25*Q25 -> 0.24896336 | T25: =RAND() -> 0.53133195 | U25: =IF(T25<EXP(-S25),0,IF(T25<EXP(-S25)*(1+S25),1,IF(T25<EXP(-S25)*(1+S25+S25^2/2),2,IF(T25<EXP(-S25)*(1+S25+S25^2/2+S25^3/6),3,4)))) -> 0 | V25: =U25*R25 -> 0 | W25: =Inputs!B15+(Inputs!D15-Inputs!B15)*BETAINV(RAND(),Model!H9,Model!I9) -> 2.1838954 | X25: =Inputs!E15+(Inputs!G15-Inputs!E15)*BETAINV(RAND(),Model!J9,Model!K9) -> 0.34124869 | Y25: =(Inputs!H15+(Inputs!J15-Inputs!H15)*BETAINV(RAND(),Model!L9,Model!M9))*Inputs!$C$6 -> 37734.667 | Z25: =W25*X25 -> 0.74525142 | AA25: =RAND() -> 0.052004822 | AB25: =IF(AA25<EXP(-Z25),0,IF(AA25<EXP(-Z25)*(1+Z25),1,IF(AA25<EXP(-Z25)*(1+Z25+Z25^2/2),2,IF(AA25<EXP(-Z25)*(1+Z25+Z25^2/2+Z25^3/6),3,4)))) -> 0 | AC25: =AB25*Y25 -> 0 | AD25: =Inputs!B16+(Inputs!D16-Inputs!B16)*BETAINV(RAND(),Model!H10,Model!I10) -> 1.0795812 | AE25: =Inputs!E16+(Inputs!G16-Inputs!E16)*BETAINV(RAND(),Model!J10,Model!K10) -> 0.61638322 | AF25: =(Inputs!H16+(Inputs!J16-Inputs!H16)*BETAINV(RAND(),Model!L10,Model!M10))*Inputs!$C$6 -> 44140.769 | AG25: =AD25*AE25 -> 0.66543571 | AH25: =RAND() -> 0.79162312 | AI25: =IF(AH25<EXP(-AG25),0,IF(AH25<EXP(-AG25)*(1+AG25),1,IF(AH25<EXP(-AG25)*(1+AG25+AG25^2/2),2,IF(AH25<EXP(-AG25)*(1+AG25+AG25^2/2+AG25^3/6),3,4)))) -> 1 | AJ25: =AI25*AF25 -> 44140.769 | AK25: =H25+O25+V25+AC25+AJ25 -> 83374.743
B26: =Inputs!B12+(Inputs!D12-Inputs!B12)*BETAINV(RAND(),Model!H6,Model!I6) -> 3.3972517 | C26: =Inputs!E12+(Inputs!G12-Inputs!E12)*BETAINV(RAND(),Model!J6,Model!K6) -> 0.42868732 | D26: =(Inputs!H12+(Inputs!J12-Inputs!H12)*BETAINV(RAND(),Model!L6,Model!M6))*Inputs!$C$6 -> 20341.637 | E26: =B26*C26 -> 1.4563587 | F26: =RAND() -> 0.22162447 | G26: =IF(F26<EXP(-E26),0,IF(F26<EXP(-E26)*(1+E26),1,IF(F26<EXP(-E26)*(1+E26+E26^2/2),2,IF(F26<EXP(-E26)*(1+E26+E26^2/2+E26^3/6),3,4)))) -> 0 | H26: =G26*D26 -> 0 | I26: =Inputs!B13+(Inputs!D13-Inputs!B13)*BETAINV(RAND(),Model!H7,Model!I7) -> 3.2120336 | J26: =Inputs!E13+(Inputs!G13-Inputs!E13)*BETAINV(RAND(),Model!J7,Model!K7) -> 0.33290504 | K26: =(Inputs!H13+(Inputs!J13-Inputs!H13)*BETAINV(RAND(),Model!L7,Model!M7))*Inputs!$C$6 -> 47946.253 | L26: =I26*J26 -> 1.0693022 | M26: =RAND() -> 0.7617418 | N26: =IF(M26<EXP(-L26),0,IF(M26<EXP(-L26)*(1+L26),1,IF(M26<EXP(-L26)*(1+L26+L26^2/2),2,IF(M26<EXP(-L26)*(1+L26+L26^2/2+L26^3/6),3,4)))) -> 2 | O26: =N26*K26 -> 95892.507 | P26: =Inputs!B14+(Inputs!D14-Inputs!B14)*BETAINV(RAND(),Model!H8,Model!I8) -> 0.1255638 | Q26: =Inputs!E14+(Inputs!G14-Inputs!E14)*BETAINV(RAND(),Model!J8,Model!K8) -> 0.64337701 | R26: =(Inputs!H14+(Inputs!J14-Inputs!H14)*BETAINV(RAND(),Model!L8,Model!M8))*Inputs!$C$6 -> 381211.2 | S26: =P26*Q26 -> 0.080784864 | T26: =RAND() -> 0.23960387 | U26: =IF(T26<EXP(-S26),0,IF(T26<EXP(-S26)*(1+S26),1,IF(T26<EXP(-S26)*(1+S26+S26^2/2),2,IF(T26<EXP(-S26)*(1+S26+S26^2/2+S26^3/6),3,4)))) -> 0 | V26: =U26*R26 -> 0 | W26: =Inputs!B15+(Inputs!D15-Inputs!B15)*BETAINV(RAND(),Model!H9,Model!I9) -> 0.59501877 | X26: =Inputs!E15+(Inputs!G15-Inputs!E15)*BETAINV(RAND(),Model!J9,Model!K9) -> 0.38093908 | Y26: =(Inputs!H15+(Inputs!J15-Inputs!H15)*BETAINV(RAND(),Model!L9,Model!M9))*Inputs!$C$6 -> 66598.116 | Z26: =W26*X26 -> 0.2266659 | AA26: =RAND() -> 0.32272239 | AB26: =IF(AA26<EXP(-Z26),0,IF(AA26<EXP(-Z26)*(1+Z26),1,IF(AA26<EXP(-Z26)*(1+Z26+Z26^2/2),2,IF(AA26<EXP(-Z26)*(1+Z26+Z26^2/2+Z26^3/6),3,4)))) -> 0 | AC26: =AB26*Y26 -> 0 | AD26: =Inputs!B16+(Inputs!D16-Inputs!B16)*BETAINV(RAND(),Model!H10,Model!I10) -> 0.52966587 | AE26: =Inputs!E16+(Inputs!G16-Inputs!E16)*BETAINV(RAND(),Model!J10,Model!K10) -> 0.70251236 | AF26: =(Inputs!H16+(Inputs!J16-Inputs!H16)*BETAINV(RAND(),Model!L10,Model!M10))*Inputs!$C$6 -> 93741.333 | AG26: =AD26*AE26 -> 0.37209682 | AH26: =RAND() -> 0.25564239 | AI26: =IF(AH26<EXP(-AG26),0,IF(AH26<EXP(-AG26)*(1+AG26),1,IF(AH26<EXP(-AG26)*(1+AG26+AG26^2/2),2,IF(AH26<EXP(-AG26)*(1+AG26+AG26^2/2+AG26^3/6),3,4)))) -> 0 | AJ26: =AI26*AF26 -> 0 | AK26: =H26+O26+V26+AC26+AJ26 -> 95892.507
B27: =Inputs!B12+(Inputs!D12-Inputs!B12)*BETAINV(RAND(),Model!H6,Model!I6) -> 4.8598189 | C27: =Inputs!E12+(Inputs!G12-Inputs!E12)*BETAINV(RAND(),Model!J6,Model!K6) -> 0.33184262 | D27: =(Inputs!H12+(Inputs!J12-Inputs!H12)*BETAINV(RAND(),Model!L6,Model!M6))*Inputs!$C$6 -> 20003.505 | E27: =B27*C27 -> 1.612695 | F27: =RAND() -> 0.28285904 | G27: =IF(F27<EXP(-E27),0,IF(F27<EXP(-E27)*(1+E27),1,IF(F27<EXP(-E27)*(1+E27+E27^2/2),2,IF(F27<EXP(-E27)*(1+E27+E27^2/2+E27^3/6),3,4)))) -> 1 | H27: =G27*D27 -> 20003.505 | I27: =Inputs!B13+(Inputs!D13-Inputs!B13)*BETAINV(RAND(),Model!H7,Model!I7) -> 1.3596487 | J27: =Inputs!E13+(Inputs!G13-Inputs!E13)*BETAINV(RAND(),Model!J7,Model!K7) -> 0.36118949 | K27: =(Inputs!H13+(Inputs!J13-Inputs!H13)*BETAINV(RAND(),Model!L7,Model!M7))*Inputs!$C$6 -> 28790.061 | L27: =I27*J27 -> 0.49109081 | M27: =RAND() -> 0.78642174 | N27: =IF(M27<EXP(-L27),0,IF(M27<EXP(-L27)*(1+L27),1,IF(M27<EXP(-L27)*(1+L27+L27^2/2),2,IF(M27<EXP(-L27)*(1+L27+L27^2/2+L27^3/6),3,4)))) -> 1 | O27: =N27*K27 -> 28790.061 | P27: =Inputs!B14+(Inputs!D14-Inputs!B14)*BETAINV(RAND(),Model!H8,Model!I8) -> 0.60717078 | Q27: =Inputs!E14+(Inputs!G14-Inputs!E14)*BETAINV(RAND(),Model!J8,Model!K8) -> 0.69374003 | R27: =(Inputs!H14+(Inputs!J14-Inputs!H14)*BETAINV(RAND(),Model!L8,Model!M8))*Inputs!$C$6 -> 294136.15 | S27: =P27*Q27 -> 0.42121868 | T27: =RAND() -> 0.35291561 | U27: =IF(T27<EXP(-S27),0,IF(T27<EXP(-S27)*(1+S27),1,IF(T27<EXP(-S27)*(1+S27+S27^2/2),2,IF(T27<EXP(-S27)*(1+S27+S27^2/2+S27^3/6),3,4)))) -> 0 | V27: =U27*R27 -> 0 | W27: =Inputs!B15+(Inputs!D15-Inputs!B15)*BETAINV(RAND(),Model!H9,Model!I9) -> 0.79675707 | X27: =Inputs!E15+(Inputs!G15-Inputs!E15)*BETAINV(RAND(),Model!J9,Model!K9) -> 0.41341462 | Y27: =(Inputs!H15+(Inputs!J15-Inputs!H15)*BETAINV(RAND(),Model!L9,Model!M9))*Inputs!$C$6 -> 10516.433 | Z27: =W27*X27 -> 0.32939102 | AA27: =RAND() -> 0.50967266 | AB27: =IF(AA27<EXP(-Z27),0,IF(AA27<EXP(-Z27)*(1+Z27),1,IF(AA27<EXP(-Z27)*(1+Z27+Z27^2/2),2,IF(AA27<EXP(-Z27)*(1+Z27+Z27^2/2+Z27^3/6),3,4)))) -> 0 | AC27: =AB27*Y27 -> 0 | AD27: =Inputs!B16+(Inputs!D16-Inputs!B16)*BETAINV(RAND(),Model!H10,Model!I10) -> 1.0307583 | AE27: =Inputs!E16+(Inputs!G16-Inputs!E16)*BETAINV(RAND(),Model!J10,Model!K10) -> 0.60606428 | AF27: =(Inputs!H16+(Inputs!J16-Inputs!H16)*BETAINV(RAND(),Model!L10,Model!M10))*Inputs!$C$6 -> 118712.17 | AG27: =AD27*AE27 -> 0.62470577 | AH27: =RAND() -> 0.49728165 | AI27: =IF(AH27<EXP(-AG27),0,IF(AH27<EXP(-AG27)*(1+AG27),1,IF(AH27<EXP(-AG27)*(1+AG27+AG27^2/2),2,IF(AH27<EXP(-AG27)*(1+AG27+AG27^2/2+AG27^3/6),3,4)))) -> 0 | AJ27: =AI27*AF27 -> 0 | AK27: =H27+O27+V27+AC27+AJ27 -> 48793.566
B28: =Inputs!B12+(Inputs!D12-Inputs!B12)*BETAINV(RAND(),Model!H6,Model!I6) -> 6.281707 | C28: =Inputs!E12+(Inputs!G12-Inputs!E12)*BETAINV(RAND(),Model!J6,Model!K6) -> 0.32344687 | D28: =(Inputs!H12+(Inputs!J12-Inputs!H12)*BETAINV(RAND(),Model!L6,Model!M6))*Inputs!$C$6 -> 26728.343 | E28: =B28*C28 -> 2.0317985 | F28: =RAND() -> 0.3235145 | G28: =IF(F28<EXP(-E28),0,IF(F28<EXP(-E28)*(1+E28),1,IF(F28<EXP(-E28)*(1+E28+E28^2/2),2,IF(F28<EXP(-E28)*(1+E28+E28^2/2+E28^3/6),3,4)))) -> 1 | H28: =G28*D28 -> 26728.343 | I28: =Inputs!B13+(Inputs!D13-Inputs!B13)*BETAINV(RAND(),Model!H7,Model!I7) -> 4.0657581 | J28: =Inputs!E13+(Inputs!G13-Inputs!E13)*BETAINV(RAND(),Model!J7,Model!K7) -> 0.30564677 | K28: =(Inputs!H13+(Inputs!J13-Inputs!H13)*BETAINV(RAND(),Model!L7,Model!M7))*Inputs!$C$6 -> 51210.572 | L28: =I28*J28 -> 1.2426858 | M28: =RAND() -> 0.75534356 | N28: =IF(M28<EXP(-L28),0,IF(M28<EXP(-L28)*(1+L28),1,IF(M28<EXP(-L28)*(1+L28+L28^2/2),2,IF(M28<EXP(-L28)*(1+L28+L28^2/2+L28^3/6),3,4)))) -> 2 | O28: =N28*K28 -> 102421.14 | P28: =Inputs!B14+(Inputs!D14-Inputs!B14)*BETAINV(RAND(),Model!H8,Model!I8) -> 0.24208878 | Q28: =Inputs!E14+(Inputs!G14-Inputs!E14)*BETAINV(RAND(),Model!J8,Model!K8) -> 0.41911428 | R28: =(Inputs!H14+(Inputs!J14-Inputs!H14)*BETAINV(RAND(),Model!L8,Model!M8))*Inputs!$C$6 -> 310280.8 | S28: =P28*Q28 -> 0.10146287 | T28: =RAND() -> 0.64052898 | U28: =IF(T28<EXP(-S28),0,IF(T28<EXP(-S28)*(1+S28),1,IF(T28<EXP(-S28)*(1+S28+S28^2/2),2,IF(T28<EXP(-S28)*(1+S28+S28^2/2+S28^3/6),3,4)))) -> 0 | V28: =U28*R28 -> 0 | W28: =Inputs!B15+(Inputs!D15-Inputs!B15)*BETAINV(RAND(),Model!H9,Model!I9) -> 1.7672386 | X28: =Inputs!E15+(Inputs!G15-Inputs!E15)*BETAINV(RAND(),Model!J9,Model!K9) -> 0.49096453 | Y28: =(Inputs!H15+(Inputs!J15-Inputs!H15)*BETAINV(RAND(),Model!L9,Model!M9))*Inputs!$C$6 -> 24942.849 | Z28: =W28*X28 -> 0.86765147 | AA28: =RAND() -> 0.31336444 | AB28: =IF(AA28<EXP(-Z28),0,IF(AA28<EXP(-Z28)*(1+Z28),1,IF(AA28<EXP(-Z28)*(1+Z28+Z28^2/2),2,IF(AA28<EXP(-Z28)*(1+Z28+Z28^2/2+Z28^3/6),3,4)))) -> 0 | AC28: =AB28*Y28 -> 0 | AD28: =Inputs!B16+(Inputs!D16-Inputs!B16)*BETAINV(RAND(),Model!H10,Model!I10) -> 0.55518083 | AE28: =Inputs!E16+(Inputs!G16-Inputs!E16)*BETAINV(RAND(),Model!J10,Model!K10) -> 0.56629698 | AF28: =(Inputs!H16+(Inputs!J16-Inputs!H16)*BETAINV(RAND(),Model!L10,Model!M10))*Inputs!$C$6 -> 89484.957 | AG28: =AD28*AE28 -> 0.31439723 | AH28: =RAND() -> 0.88955852 | AI28: =IF(AH28<EXP(-AG28),0,IF(AH28<EXP(-AG28)*(1+AG28),1,IF(AH28<EXP(-AG28)*(1+AG28+AG28^2/2),2,IF(AH28<EXP(-AG28)*(1+AG28+AG28^2/2+AG28^3/6),3,4)))) -> 1 | AJ28: =AI28*AF28 -> 89484.957 | AK28: =H28+O28+V28+AC28+AJ28 -> 218634.45
B29: =Inputs!B12+(Inputs!D12-Inputs!B12)*BETAINV(RAND(),Model!H6,Model!I6) -> 2.3542727 | C29: =Inputs!E12+(Inputs!G12-Inputs!E12)*BETAINV(RAND(),Model!J6,Model!K6) -> 0.37073496 | D29: =(Inputs!H12+(Inputs!J12-Inputs!H12)*BETAINV(RAND(),Model!L6,Model!M6))*Inputs!$C$6 -> 37681.33 | E29: =B29*C29 -> 0.87281119 | F29: =RAND() -> 0.90882717 | G29: =IF(F29<EXP(-E29),0,IF(F29<EXP(-E29)*(1+E29),1,IF(F29<EXP(-E29)*(1+E29+E29^2/2),2,IF(F29<EXP(-E29)*(1+E29+E29^2/2+E29^3/6),3,4)))) -> 2 | H29: =G29*D29 -> 75362.661 | I29: =Inputs!B13+(Inputs!D13-Inputs!B13)*BETAINV(RAND(),Model!H7,Model!I7) -> 1.0500941 | J29: =Inputs!E13+(Inputs!G13-Inputs!E13)*BETAINV(RAND(),Model!J7,Model!K7) -> 0.15397051 | K29: =(Inputs!H13+(Inputs!J13-Inputs!H13)*BETAINV(RAND(),Model!L7,Model!M7))*Inputs!$C$6 -> 13797.343 | L29: =I29*J29 -> 0.16168352 | M29: =RAND() -> 0.074584895 | N29: =IF(M29<EXP(-L29),0,IF(M29<EXP(-L29)*(1+L29),1,IF(M29<EXP(-L29)*(1+L29+L29^2/2),2,IF(M29<EXP(-L29)*(1+L29+L29^2/2+L29^3/6),3,4)))) -> 0 | O29: =N29*K29 -> 0 | P29: =Inputs!B14+(Inputs!D14-Inputs!B14)*BETAINV(RAND(),Model!H8,Model!I8) -> 0.49699146 | Q29: =Inputs!E14+(Inputs!G14-Inputs!E14)*BETAINV(RAND(),Model!J8,Model!K8) -> 0.56714315 | R29: =(Inputs!H14+(Inputs!J14-Inputs!H14)*BETAINV(RAND(),Model!L8,Model!M8))*Inputs!$C$6 -> 323408.01 | S29: =P29*Q29 -> 0.2818653 | T29: =RAND() -> 0.52921237 | U29: =IF(T29<EXP(-S29),0,IF(T29<EXP(-S29)*(1+S29),1,IF(T29<EXP(-S29)*(1+S29+S29^2/2),2,IF(T29<EXP(-S29)*(1+S29+S29^2/2+S29^3/6),3,4)))) -> 0 | V29: =U29*R29 -> 0 | W29: =Inputs!B15+(Inputs!D15-Inputs!B15)*BETAINV(RAND(),Model!H9,Model!I9) -> 0.37374604 | X29: =Inputs!E15+(Inputs!G15-Inputs!E15)*BETAINV(RAND(),Model!J9,Model!K9) -> 0.28291467 | Y29: =(Inputs!H15+(Inputs!J15-Inputs!H15)*BETAINV(RAND(),Model!L9,Model!M9))*Inputs!$C$6 -> 67199.958 | Z29: =W29*X29 -> 0.10573824 | AA29: =RAND() -> 0.64324142 | AB29: =IF(AA29<EXP(-Z29),0,IF(AA29<EXP(-Z29)*(1+Z29),1,IF(AA29<EXP(-Z29)*(1+Z29+Z29^2/2),2,IF(AA29<EXP(-Z29)*(1+Z29+Z29^2/2+Z29^3/6),3,4)))) -> 0 | AC29: =AB29*Y29 -> 0 | AD29: =Inputs!B16+(Inputs!D16-Inputs!B16)*BETAINV(RAND(),Model!H10,Model!I10) -> 0.78637055 | AE29: =Inputs!E16+(Inputs!G16-Inputs!E16)*BETAINV(RAND(),Model!J10,Model!K10) -> 0.64310758 | AF29: =(Inputs!H16+(Inputs!J16-Inputs!H16)*BETAINV(RAND(),Model!L10,Model!M10))*Inputs!$C$6 -> 85892.976 | AG29: =AD29*AE29 -> 0.50572086 | AH29: =RAND() -> 0.40322182 | AI29: =IF(AH29<EXP(-AG29),0,IF(AH29<EXP(-AG29)*(1+AG29),1,IF(AH29<EXP(-AG29)*(1+AG29+AG29^2/2),2,IF(AH29<EXP(-AG29)*(1+AG29+AG29^2/2+AG29^3/6),3,4)))) -> 0 | AJ29: =AI29*AF29 -> 0 | AK29: =H29+O29+V29+AC29+AJ29 -> 75362.661
